package net.essence.dimension.frozen.gen;

import net.minecraft.world.gen.feature.*;
import net.minecraft.world.*;
import java.util.*;
import net.essence.*;
import net.minecraft.init.*;
import net.minecraft.block.*;
import net.minecraft.item.*;

public class WorldGenSantasWorkshop extends WorldGenerator
{
    public boolean generate(final World world, final Random rand, final int i, final int j, final int k) {
        final Block carpet = EssenceBlocks.workshopCarpet;
        final Block glass = EssenceBlocks.frozenGlass;
        final Block slab = EssenceBlocks.workshopSlab;
        final Block stair = EssenceBlocks.workshopStoneStair;
        final Block pane = EssenceBlocks.frozenPane;
        final Block stone = EssenceBlocks.workshopStone;
        final Block fence = EssenceBlocks.workshopStoneFence;
        final Block lamp = EssenceBlocks.workshopLamp;
        final Block door = EssenceBlocks.frozenDoor;
        world.setBlock(i + 0, j + 0, k + 0, carpet);
        world.setBlock(i + 0, j + 0, k + 1, carpet);
        world.setBlock(i + 0, j + 0, k + 2, carpet);
        world.setBlock(i + 0, j + 0, k + 3, carpet);
        world.setBlock(i + 0, j + 0, k + 4, carpet);
        world.setBlock(i + 0, j + 0, k + 5, carpet);
        world.setBlock(i + 0, j + 0, k + 6, carpet);
        world.setBlock(i + 0, j + 0, k + 7, carpet);
        world.setBlock(i + 0, j + 0, k + 8, carpet);
        world.setBlock(i + 0, j + 0, k + 9, carpet);
        world.setBlock(i + 0, j + 0, k + 10, carpet);
        world.setBlock(i + 0, j + 0, k + 11, carpet);
        world.setBlock(i + 0, j + 0, k + 12, carpet);
        world.setBlock(i + 0, j + 0, k + 13, carpet);
        world.setBlock(i + 0, j + 0, k + 14, carpet);
        world.setBlock(i + 0, j + 0, k + 15, carpet);
        world.setBlock(i + 0, j + 0, k + 16, carpet);
        world.setBlock(i + 0, j + 0, k + 17, carpet);
        world.setBlock(i + 0, j + 1, k + 0, glass);
        world.setBlock(i + 0, j + 1, k + 1, glass);
        world.setBlock(i + 0, j + 1, k + 2, glass);
        world.setBlock(i + 0, j + 1, k + 3, glass);
        world.setBlock(i + 0, j + 1, k + 4, glass);
        world.setBlock(i + 0, j + 1, k + 5, glass);
        world.setBlock(i + 0, j + 1, k + 6, glass);
        world.setBlock(i + 0, j + 1, k + 7, glass);
        world.setBlock(i + 0, j + 1, k + 10, glass);
        world.setBlock(i + 0, j + 1, k + 11, glass);
        world.setBlock(i + 0, j + 1, k + 12, glass);
        world.setBlock(i + 0, j + 1, k + 13, glass);
        world.setBlock(i + 0, j + 1, k + 14, glass);
        world.setBlock(i + 0, j + 1, k + 15, glass);
        world.setBlock(i + 0, j + 1, k + 16, glass);
        world.setBlock(i + 0, j + 1, k + 17, glass);
        world.setBlock(i + 0, j + 2, k + 0, glass);
        world.setBlock(i + 0, j + 2, k + 1, glass);
        world.setBlock(i + 0, j + 2, k + 2, glass);
        world.setBlock(i + 0, j + 2, k + 3, glass);
        world.setBlock(i + 0, j + 2, k + 4, glass);
        world.setBlock(i + 0, j + 2, k + 5, glass);
        world.setBlock(i + 0, j + 2, k + 6, glass);
        world.setBlock(i + 0, j + 2, k + 7, glass);
        world.setBlock(i + 0, j + 2, k + 10, glass);
        world.setBlock(i + 0, j + 2, k + 11, glass);
        world.setBlock(i + 0, j + 2, k + 12, glass);
        world.setBlock(i + 0, j + 2, k + 13, glass);
        world.setBlock(i + 0, j + 2, k + 14, glass);
        world.setBlock(i + 0, j + 2, k + 15, glass);
        world.setBlock(i + 0, j + 2, k + 16, glass);
        world.setBlock(i + 0, j + 2, k + 17, glass);
        world.setBlock(i + 0, j + 3, k + 0, glass);
        world.setBlock(i + 0, j + 3, k + 1, glass);
        world.setBlock(i + 0, j + 3, k + 2, glass);
        world.setBlock(i + 0, j + 3, k + 3, glass);
        world.setBlock(i + 0, j + 3, k + 4, glass);
        world.setBlock(i + 0, j + 3, k + 5, glass);
        world.setBlock(i + 0, j + 3, k + 6, glass);
        world.setBlock(i + 0, j + 3, k + 7, glass);
        world.setBlock(i + 0, j + 3, k + 8, glass);
        world.setBlock(i + 0, j + 3, k + 9, glass);
        world.setBlock(i + 0, j + 3, k + 10, glass);
        world.setBlock(i + 0, j + 3, k + 11, glass);
        world.setBlock(i + 0, j + 3, k + 12, glass);
        world.setBlock(i + 0, j + 3, k + 13, glass);
        world.setBlock(i + 0, j + 3, k + 14, glass);
        world.setBlock(i + 0, j + 3, k + 15, glass);
        world.setBlock(i + 0, j + 3, k + 16, glass);
        world.setBlock(i + 0, j + 3, k + 17, glass);
        world.setBlock(i + 0, j + 4, k + 0, glass);
        world.setBlock(i + 0, j + 4, k + 1, glass);
        world.setBlock(i + 0, j + 4, k + 2, glass);
        world.setBlock(i + 0, j + 4, k + 3, glass);
        world.setBlock(i + 0, j + 4, k + 4, glass);
        world.setBlock(i + 0, j + 4, k + 5, glass);
        world.setBlock(i + 0, j + 4, k + 6, glass);
        world.setBlock(i + 0, j + 4, k + 7, glass);
        world.setBlock(i + 0, j + 4, k + 8, glass);
        world.setBlock(i + 0, j + 4, k + 9, glass);
        world.setBlock(i + 0, j + 4, k + 10, glass);
        world.setBlock(i + 0, j + 4, k + 11, glass);
        world.setBlock(i + 0, j + 4, k + 12, glass);
        world.setBlock(i + 0, j + 4, k + 13, glass);
        world.setBlock(i + 0, j + 4, k + 14, glass);
        world.setBlock(i + 0, j + 4, k + 15, glass);
        world.setBlock(i + 0, j + 4, k + 16, glass);
        world.setBlock(i + 0, j + 4, k + 17, glass);
        world.setBlock(i + 0, j + 5, k + 0, glass);
        world.setBlock(i + 0, j + 5, k + 1, glass);
        world.setBlock(i + 0, j + 5, k + 2, glass);
        world.setBlock(i + 0, j + 5, k + 3, glass);
        world.setBlock(i + 0, j + 5, k + 4, glass);
        world.setBlock(i + 0, j + 5, k + 5, glass);
        world.setBlock(i + 0, j + 5, k + 6, glass);
        world.setBlock(i + 0, j + 5, k + 7, glass);
        world.setBlock(i + 0, j + 5, k + 8, glass);
        world.setBlock(i + 0, j + 5, k + 9, glass);
        world.setBlock(i + 0, j + 5, k + 10, glass);
        world.setBlock(i + 0, j + 5, k + 11, glass);
        world.setBlock(i + 0, j + 5, k + 12, glass);
        world.setBlock(i + 0, j + 5, k + 13, glass);
        world.setBlock(i + 0, j + 5, k + 14, glass);
        world.setBlock(i + 0, j + 5, k + 15, glass);
        world.setBlock(i + 0, j + 5, k + 16, glass);
        world.setBlock(i + 0, j + 5, k + 17, glass);
        world.setBlock(i + 0, j + 6, k + 0, glass);
        world.setBlock(i + 0, j + 6, k + 1, glass);
        world.setBlock(i + 0, j + 6, k + 2, glass);
        world.setBlock(i + 0, j + 6, k + 3, glass);
        world.setBlock(i + 0, j + 6, k + 4, glass);
        world.setBlock(i + 0, j + 6, k + 5, glass);
        world.setBlock(i + 0, j + 6, k + 6, glass);
        world.setBlock(i + 0, j + 6, k + 7, glass);
        world.setBlock(i + 0, j + 6, k + 8, glass);
        world.setBlock(i + 0, j + 6, k + 9, glass);
        world.setBlock(i + 0, j + 6, k + 10, glass);
        world.setBlock(i + 0, j + 6, k + 11, glass);
        world.setBlock(i + 0, j + 6, k + 12, glass);
        world.setBlock(i + 0, j + 6, k + 13, glass);
        world.setBlock(i + 0, j + 6, k + 14, glass);
        world.setBlock(i + 0, j + 6, k + 15, glass);
        world.setBlock(i + 0, j + 6, k + 16, glass);
        world.setBlock(i + 0, j + 6, k + 17, glass);
        world.setBlock(i + 0, j + 7, k + 0, glass);
        world.setBlock(i + 0, j + 7, k + 1, glass);
        world.setBlock(i + 0, j + 7, k + 2, glass);
        world.setBlock(i + 0, j + 7, k + 3, glass);
        world.setBlock(i + 0, j + 7, k + 4, glass);
        world.setBlock(i + 0, j + 7, k + 5, glass);
        world.setBlock(i + 0, j + 7, k + 6, glass);
        world.setBlock(i + 0, j + 7, k + 7, glass);
        world.setBlock(i + 0, j + 7, k + 8, glass);
        world.setBlock(i + 0, j + 7, k + 9, glass);
        world.setBlock(i + 0, j + 7, k + 10, glass);
        world.setBlock(i + 0, j + 7, k + 11, glass);
        world.setBlock(i + 0, j + 7, k + 12, glass);
        world.setBlock(i + 0, j + 7, k + 13, glass);
        world.setBlock(i + 0, j + 7, k + 14, glass);
        world.setBlock(i + 0, j + 7, k + 15, glass);
        world.setBlock(i + 0, j + 7, k + 16, glass);
        world.setBlock(i + 0, j + 7, k + 17, glass);
        world.setBlock(i + 0, j + 8, k + 0, glass);
        world.setBlock(i + 0, j + 8, k + 1, glass);
        world.setBlock(i + 0, j + 8, k + 2, glass);
        world.setBlock(i + 0, j + 8, k + 3, glass);
        world.setBlock(i + 0, j + 8, k + 4, glass);
        world.setBlock(i + 0, j + 8, k + 5, glass);
        world.setBlock(i + 0, j + 8, k + 6, glass);
        world.setBlock(i + 0, j + 8, k + 7, glass);
        world.setBlock(i + 0, j + 8, k + 8, glass);
        world.setBlock(i + 0, j + 8, k + 9, glass);
        world.setBlock(i + 0, j + 8, k + 10, glass);
        world.setBlock(i + 0, j + 8, k + 11, glass);
        world.setBlock(i + 0, j + 8, k + 12, glass);
        world.setBlock(i + 0, j + 8, k + 13, glass);
        world.setBlock(i + 0, j + 8, k + 14, glass);
        world.setBlock(i + 0, j + 8, k + 15, glass);
        world.setBlock(i + 0, j + 8, k + 16, glass);
        world.setBlock(i + 0, j + 8, k + 17, glass);
        world.setBlock(i + 0, j + 9, k + 0, glass);
        world.setBlock(i + 0, j + 9, k + 1, glass);
        world.setBlock(i + 0, j + 9, k + 2, glass);
        world.setBlock(i + 0, j + 9, k + 3, glass);
        world.setBlock(i + 0, j + 9, k + 4, glass);
        world.setBlock(i + 0, j + 9, k + 5, glass);
        world.setBlock(i + 0, j + 9, k + 6, glass);
        world.setBlock(i + 0, j + 9, k + 7, glass);
        world.setBlock(i + 0, j + 9, k + 8, glass);
        world.setBlock(i + 0, j + 9, k + 9, glass);
        world.setBlock(i + 0, j + 9, k + 10, glass);
        world.setBlock(i + 0, j + 9, k + 11, glass);
        world.setBlock(i + 0, j + 9, k + 12, glass);
        world.setBlock(i + 0, j + 9, k + 13, glass);
        world.setBlock(i + 0, j + 9, k + 14, glass);
        world.setBlock(i + 0, j + 9, k + 15, glass);
        world.setBlock(i + 0, j + 9, k + 16, glass);
        world.setBlock(i + 0, j + 9, k + 17, glass);
        world.setBlock(i + 0, j + 10, k + 0, glass);
        world.setBlock(i + 0, j + 10, k + 1, glass);
        world.setBlock(i + 0, j + 10, k + 2, glass);
        world.setBlock(i + 0, j + 10, k + 3, glass);
        world.setBlock(i + 0, j + 10, k + 4, glass);
        world.setBlock(i + 0, j + 10, k + 5, glass);
        world.setBlock(i + 0, j + 10, k + 6, glass);
        world.setBlock(i + 0, j + 10, k + 7, glass);
        world.setBlock(i + 0, j + 10, k + 8, glass);
        world.setBlock(i + 0, j + 10, k + 9, glass);
        world.setBlock(i + 0, j + 10, k + 10, glass);
        world.setBlock(i + 0, j + 10, k + 11, glass);
        world.setBlock(i + 0, j + 10, k + 12, glass);
        world.setBlock(i + 0, j + 10, k + 13, glass);
        world.setBlock(i + 0, j + 10, k + 14, glass);
        world.setBlock(i + 0, j + 10, k + 15, glass);
        world.setBlock(i + 0, j + 10, k + 16, glass);
        world.setBlock(i + 0, j + 10, k + 17, glass);
        world.setBlock(i + 0, j + 11, k + 0, glass);
        world.setBlock(i + 0, j + 11, k + 1, glass);
        world.setBlock(i + 0, j + 11, k + 2, glass);
        world.setBlock(i + 0, j + 11, k + 3, glass);
        world.setBlock(i + 0, j + 11, k + 4, glass);
        world.setBlock(i + 0, j + 11, k + 5, glass);
        world.setBlock(i + 0, j + 11, k + 6, glass);
        world.setBlock(i + 0, j + 11, k + 7, glass);
        world.setBlock(i + 0, j + 11, k + 8, glass);
        world.setBlock(i + 0, j + 11, k + 9, glass);
        world.setBlock(i + 0, j + 11, k + 10, glass);
        world.setBlock(i + 0, j + 11, k + 11, glass);
        world.setBlock(i + 0, j + 11, k + 12, glass);
        world.setBlock(i + 0, j + 11, k + 13, glass);
        world.setBlock(i + 0, j + 11, k + 14, glass);
        world.setBlock(i + 0, j + 11, k + 15, glass);
        world.setBlock(i + 0, j + 11, k + 16, glass);
        world.setBlock(i + 0, j + 11, k + 17, glass);
        world.setBlock(i + 0, j + 12, k + 0, glass);
        world.setBlock(i + 0, j + 12, k + 1, glass);
        world.setBlock(i + 0, j + 12, k + 2, glass);
        world.setBlock(i + 0, j + 12, k + 3, glass);
        world.setBlock(i + 0, j + 12, k + 4, glass);
        world.setBlock(i + 0, j + 12, k + 5, glass);
        world.setBlock(i + 0, j + 12, k + 6, glass);
        world.setBlock(i + 0, j + 12, k + 7, glass);
        world.setBlock(i + 0, j + 12, k + 8, glass);
        world.setBlock(i + 0, j + 12, k + 9, glass);
        world.setBlock(i + 0, j + 12, k + 10, glass);
        world.setBlock(i + 0, j + 12, k + 11, glass);
        world.setBlock(i + 0, j + 12, k + 12, glass);
        world.setBlock(i + 0, j + 12, k + 13, glass);
        world.setBlock(i + 0, j + 12, k + 14, glass);
        world.setBlock(i + 0, j + 12, k + 15, glass);
        world.setBlock(i + 0, j + 12, k + 16, glass);
        world.setBlock(i + 0, j + 12, k + 17, glass);
        world.setBlock(i + 0, j + 13, k + 0, glass);
        world.setBlock(i + 0, j + 13, k + 1, glass);
        world.setBlock(i + 0, j + 13, k + 2, glass);
        world.setBlock(i + 0, j + 13, k + 3, glass);
        world.setBlock(i + 0, j + 13, k + 4, glass);
        world.setBlock(i + 0, j + 13, k + 5, glass);
        world.setBlock(i + 0, j + 13, k + 6, glass);
        world.setBlock(i + 0, j + 13, k + 7, glass);
        world.setBlock(i + 0, j + 13, k + 8, glass);
        world.setBlock(i + 0, j + 13, k + 9, glass);
        world.setBlock(i + 0, j + 13, k + 10, glass);
        world.setBlock(i + 0, j + 13, k + 11, glass);
        world.setBlock(i + 0, j + 13, k + 12, glass);
        world.setBlock(i + 0, j + 13, k + 13, glass);
        world.setBlock(i + 0, j + 13, k + 14, glass);
        world.setBlock(i + 0, j + 13, k + 15, glass);
        world.setBlock(i + 0, j + 13, k + 16, glass);
        world.setBlock(i + 0, j + 13, k + 17, glass);
        world.setBlock(i + 0, j + 14, k + 0, glass);
        world.setBlock(i + 0, j + 14, k + 1, glass);
        world.setBlock(i + 0, j + 14, k + 2, glass);
        world.setBlock(i + 0, j + 14, k + 3, glass);
        world.setBlock(i + 0, j + 14, k + 4, glass);
        world.setBlock(i + 0, j + 14, k + 5, glass);
        world.setBlock(i + 0, j + 14, k + 6, glass);
        world.setBlock(i + 0, j + 14, k + 7, glass);
        world.setBlock(i + 0, j + 14, k + 8, glass);
        world.setBlock(i + 0, j + 14, k + 9, glass);
        world.setBlock(i + 0, j + 14, k + 10, glass);
        world.setBlock(i + 0, j + 14, k + 11, glass);
        world.setBlock(i + 0, j + 14, k + 12, glass);
        world.setBlock(i + 0, j + 14, k + 13, glass);
        world.setBlock(i + 0, j + 14, k + 14, glass);
        world.setBlock(i + 0, j + 14, k + 15, glass);
        world.setBlock(i + 0, j + 14, k + 16, glass);
        world.setBlock(i + 0, j + 14, k + 17, glass);
        world.setBlock(i + 0, j + 15, k + 0, glass);
        world.setBlock(i + 0, j + 15, k + 1, glass);
        world.setBlock(i + 0, j + 15, k + 2, glass);
        world.setBlock(i + 0, j + 15, k + 3, glass);
        world.setBlock(i + 0, j + 15, k + 4, glass);
        world.setBlock(i + 0, j + 15, k + 5, glass);
        world.setBlock(i + 0, j + 15, k + 6, glass);
        world.setBlock(i + 0, j + 15, k + 7, glass);
        world.setBlock(i + 0, j + 15, k + 8, glass);
        world.setBlock(i + 0, j + 15, k + 9, glass);
        world.setBlock(i + 0, j + 15, k + 10, glass);
        world.setBlock(i + 0, j + 15, k + 11, glass);
        world.setBlock(i + 0, j + 15, k + 12, glass);
        world.setBlock(i + 0, j + 15, k + 13, glass);
        world.setBlock(i + 0, j + 15, k + 14, glass);
        world.setBlock(i + 0, j + 15, k + 15, glass);
        world.setBlock(i + 0, j + 15, k + 16, glass);
        world.setBlock(i + 0, j + 15, k + 17, glass);
        world.setBlock(i + 0, j + 16, k + 0, glass);
        world.setBlock(i + 0, j + 16, k + 1, glass);
        world.setBlock(i + 0, j + 16, k + 2, glass);
        world.setBlock(i + 0, j + 16, k + 3, glass);
        world.setBlock(i + 0, j + 16, k + 4, glass);
        world.setBlock(i + 0, j + 16, k + 5, glass);
        world.setBlock(i + 0, j + 16, k + 6, glass);
        world.setBlock(i + 0, j + 16, k + 7, glass);
        world.setBlock(i + 0, j + 16, k + 8, glass);
        world.setBlock(i + 0, j + 16, k + 9, glass);
        world.setBlock(i + 0, j + 16, k + 10, glass);
        world.setBlock(i + 0, j + 16, k + 11, glass);
        world.setBlock(i + 0, j + 16, k + 12, glass);
        world.setBlock(i + 0, j + 16, k + 13, glass);
        world.setBlock(i + 0, j + 16, k + 14, glass);
        world.setBlock(i + 0, j + 16, k + 15, glass);
        world.setBlock(i + 0, j + 16, k + 16, glass);
        world.setBlock(i + 0, j + 16, k + 17, glass);
        world.setBlock(i + 0, j + 17, k + 0, glass);
        world.setBlock(i + 0, j + 17, k + 1, glass);
        world.setBlock(i + 0, j + 17, k + 2, glass);
        world.setBlock(i + 0, j + 17, k + 3, glass);
        world.setBlock(i + 0, j + 17, k + 4, glass);
        world.setBlock(i + 0, j + 17, k + 5, glass);
        world.setBlock(i + 0, j + 17, k + 6, glass);
        world.setBlock(i + 0, j + 17, k + 7, glass);
        world.setBlock(i + 0, j + 17, k + 8, glass);
        world.setBlock(i + 0, j + 17, k + 9, glass);
        world.setBlock(i + 0, j + 17, k + 10, glass);
        world.setBlock(i + 0, j + 17, k + 11, glass);
        world.setBlock(i + 0, j + 17, k + 12, glass);
        world.setBlock(i + 0, j + 17, k + 13, glass);
        world.setBlock(i + 0, j + 17, k + 14, glass);
        world.setBlock(i + 0, j + 17, k + 15, glass);
        world.setBlock(i + 0, j + 17, k + 16, glass);
        world.setBlock(i + 0, j + 17, k + 17, glass);
        world.setBlock(i + 0, j + 18, k + 0, glass);
        world.setBlock(i + 0, j + 18, k + 1, glass);
        world.setBlock(i + 0, j + 18, k + 2, glass);
        world.setBlock(i + 0, j + 18, k + 3, glass);
        world.setBlock(i + 0, j + 18, k + 4, glass);
        world.setBlock(i + 0, j + 18, k + 5, glass);
        world.setBlock(i + 0, j + 18, k + 6, glass);
        world.setBlock(i + 0, j + 18, k + 7, glass);
        world.setBlock(i + 0, j + 18, k + 8, glass);
        world.setBlock(i + 0, j + 18, k + 9, glass);
        world.setBlock(i + 0, j + 18, k + 10, glass);
        world.setBlock(i + 0, j + 18, k + 11, glass);
        world.setBlock(i + 0, j + 18, k + 12, glass);
        world.setBlock(i + 0, j + 18, k + 13, glass);
        world.setBlock(i + 0, j + 18, k + 14, glass);
        world.setBlock(i + 0, j + 18, k + 15, glass);
        world.setBlock(i + 0, j + 18, k + 16, glass);
        world.setBlock(i + 0, j + 18, k + 17, glass);
        world.setBlock(i + 0, j + 19, k + 0, glass);
        world.setBlock(i + 0, j + 19, k + 1, glass);
        world.setBlock(i + 0, j + 19, k + 2, glass);
        world.setBlock(i + 0, j + 19, k + 3, glass);
        world.setBlock(i + 0, j + 19, k + 4, glass);
        world.setBlock(i + 0, j + 19, k + 5, glass);
        world.setBlock(i + 0, j + 19, k + 6, glass);
        world.setBlock(i + 0, j + 19, k + 7, glass);
        world.setBlock(i + 0, j + 19, k + 8, glass);
        world.setBlock(i + 0, j + 19, k + 9, glass);
        world.setBlock(i + 0, j + 19, k + 10, glass);
        world.setBlock(i + 0, j + 19, k + 11, glass);
        world.setBlock(i + 0, j + 19, k + 12, glass);
        world.setBlock(i + 0, j + 19, k + 13, glass);
        world.setBlock(i + 0, j + 19, k + 14, glass);
        world.setBlock(i + 0, j + 19, k + 15, glass);
        world.setBlock(i + 0, j + 19, k + 16, glass);
        world.setBlock(i + 0, j + 19, k + 17, glass);
        world.setBlock(i + 0, j + 20, k + 0, glass);
        world.setBlock(i + 0, j + 20, k + 1, glass);
        world.setBlock(i + 0, j + 20, k + 2, glass);
        world.setBlock(i + 0, j + 20, k + 3, glass);
        world.setBlock(i + 0, j + 20, k + 4, glass);
        world.setBlock(i + 0, j + 20, k + 5, glass);
        world.setBlock(i + 0, j + 20, k + 6, glass);
        world.setBlock(i + 0, j + 20, k + 7, glass);
        world.setBlock(i + 0, j + 20, k + 8, glass);
        world.setBlock(i + 0, j + 20, k + 9, glass);
        world.setBlock(i + 0, j + 20, k + 10, glass);
        world.setBlock(i + 0, j + 20, k + 11, glass);
        world.setBlock(i + 0, j + 20, k + 12, glass);
        world.setBlock(i + 0, j + 20, k + 13, glass);
        world.setBlock(i + 0, j + 20, k + 14, glass);
        world.setBlock(i + 0, j + 20, k + 15, glass);
        world.setBlock(i + 0, j + 20, k + 16, glass);
        world.setBlock(i + 0, j + 20, k + 17, glass);
        world.setBlock(i + 0, j + 21, k + 0, glass);
        world.setBlock(i + 0, j + 21, k + 1, glass);
        world.setBlock(i + 0, j + 21, k + 2, glass);
        world.setBlock(i + 0, j + 21, k + 3, glass);
        world.setBlock(i + 0, j + 21, k + 4, glass);
        world.setBlock(i + 0, j + 21, k + 5, glass);
        world.setBlock(i + 0, j + 21, k + 6, glass);
        world.setBlock(i + 0, j + 21, k + 7, glass);
        world.setBlock(i + 0, j + 21, k + 8, glass);
        world.setBlock(i + 0, j + 21, k + 9, glass);
        world.setBlock(i + 0, j + 21, k + 10, glass);
        world.setBlock(i + 0, j + 21, k + 11, glass);
        world.setBlock(i + 0, j + 21, k + 12, glass);
        world.setBlock(i + 0, j + 21, k + 13, glass);
        world.setBlock(i + 0, j + 21, k + 14, glass);
        world.setBlock(i + 0, j + 21, k + 15, glass);
        world.setBlock(i + 0, j + 21, k + 16, glass);
        world.setBlock(i + 0, j + 21, k + 17, glass);
        world.setBlock(i + 1, j + 0, k + 0, carpet);
        world.setBlock(i + 1, j + 0, k + 1, carpet);
        world.setBlock(i + 1, j + 0, k + 2, carpet);
        world.setBlock(i + 1, j + 0, k + 3, carpet);
        world.setBlock(i + 1, j + 0, k + 4, carpet);
        world.setBlock(i + 1, j + 0, k + 5, carpet);
        world.setBlock(i + 1, j + 0, k + 6, carpet);
        world.setBlock(i + 1, j + 0, k + 7, carpet);
        world.setBlock(i + 1, j + 0, k + 8, carpet);
        world.setBlock(i + 1, j + 0, k + 9, carpet);
        world.setBlock(i + 1, j + 0, k + 10, carpet);
        world.setBlock(i + 1, j + 0, k + 11, carpet);
        world.setBlock(i + 1, j + 0, k + 12, carpet);
        world.setBlock(i + 1, j + 0, k + 13, carpet);
        world.setBlock(i + 1, j + 0, k + 14, carpet);
        world.setBlock(i + 1, j + 0, k + 15, carpet);
        world.setBlock(i + 1, j + 0, k + 16, carpet);
        world.setBlock(i + 1, j + 0, k + 17, carpet);
        world.setBlock(i + 1, j + 1, k + 0, glass);
        world.setBlock(i + 1, j + 1, k + 17, glass);
        world.setBlock(i + 1, j + 2, k + 0, glass);
        world.setBlock(i + 1, j + 2, k + 17, glass);
        world.setBlock(i + 1, j + 3, k + 0, glass);
        world.setBlock(i + 1, j + 3, k + 17, glass);
        world.setBlock(i + 1, j + 4, k + 0, glass);
        world.setBlock(i + 1, j + 4, k + 17, glass);
        world.setBlock(i + 1, j + 5, k + 0, glass);
        world.setBlock(i + 1, j + 5, k + 17, glass);
        world.setBlock(i + 1, j + 6, k + 0, glass);
        world.setBlock(i + 1, j + 6, k + 17, glass);
        world.setBlock(i + 1, j + 7, k + 0, glass);
        world.setBlock(i + 1, j + 7, k + 1, carpet);
        world.setBlock(i + 1, j + 7, k + 2, carpet);
        world.setBlock(i + 1, j + 7, k + 3, carpet);
        world.setBlock(i + 1, j + 7, k + 4, carpet);
        world.setBlock(i + 1, j + 7, k + 5, carpet);
        world.setBlock(i + 1, j + 7, k + 6, carpet);
        world.setBlock(i + 1, j + 7, k + 7, carpet);
        world.setBlock(i + 1, j + 7, k + 8, carpet);
        world.setBlock(i + 1, j + 7, k + 9, carpet);
        world.setBlock(i + 1, j + 7, k + 10, carpet);
        world.setBlock(i + 1, j + 7, k + 11, carpet);
        world.setBlock(i + 1, j + 7, k + 12, carpet);
        world.setBlock(i + 1, j + 7, k + 13, carpet);
        world.setBlock(i + 1, j + 7, k + 14, carpet);
        world.setBlock(i + 1, j + 7, k + 15, carpet);
        world.setBlock(i + 1, j + 7, k + 16, carpet);
        world.setBlock(i + 1, j + 7, k + 17, glass);
        world.setBlock(i + 1, j + 8, k + 0, glass);
        world.setBlock(i + 1, j + 8, k + 1, lamp);
        world.setBlock(i + 1, j + 8, k + 2, carpet);
        world.setBlock(i + 1, j + 8, k + 3, carpet);
        world.setBlock(i + 1, j + 8, k + 4, carpet);
        world.setBlock(i + 1, j + 8, k + 5, carpet);
        world.setBlock(i + 1, j + 8, k + 6, carpet);
        world.setBlock(i + 1, j + 8, k + 7, carpet);
        world.setBlock(i + 1, j + 8, k + 8, carpet);
        world.setBlock(i + 1, j + 8, k + 9, carpet);
        world.setBlock(i + 1, j + 8, k + 10, carpet);
        world.setBlock(i + 1, j + 8, k + 11, carpet);
        world.setBlock(i + 1, j + 8, k + 12, carpet);
        world.setBlock(i + 1, j + 8, k + 13, carpet);
        world.setBlock(i + 1, j + 8, k + 14, carpet);
        world.setBlock(i + 1, j + 8, k + 15, carpet);
        world.setBlock(i + 1, j + 8, k + 16, lamp);
        world.setBlock(i + 1, j + 8, k + 17, glass);
        world.setBlock(i + 1, j + 9, k + 0, glass);
        world.setBlock(i + 1, j + 9, k + 3, stair, 2, 2);
        world.setBlock(i + 1, j + 9, k + 4, stone);
        world.setBlock(i + 1, j + 9, k + 5, stone);
        world.setBlock(i + 1, j + 9, k + 6, stone);
        world.setBlock(i + 1, j + 9, k + 7, stone);
        world.setBlock(i + 1, j + 9, k + 8, stone);
        world.setBlock(i + 1, j + 9, k + 9, stone);
        world.setBlock(i + 1, j + 9, k + 10, stone);
        world.setBlock(i + 1, j + 9, k + 11, stone);
        world.setBlock(i + 1, j + 9, k + 12, stone);
        world.setBlock(i + 1, j + 9, k + 13, stone);
        world.setBlock(i + 1, j + 9, k + 14, stair, 3, 2);
        world.setBlock(i + 1, j + 9, k + 17, glass);
        world.setBlock(i + 1, j + 10, k + 0, glass);
        world.setBlock(i + 1, j + 10, k + 4, stair, 2, 2);
        world.setBlock(i + 1, j + 10, k + 5, stone);
        world.setBlock(i + 1, j + 10, k + 6, stone);
        world.setBlock(i + 1, j + 10, k + 7, stone);
        world.setBlock(i + 1, j + 10, k + 8, stone);
        world.setBlock(i + 1, j + 10, k + 9, stone);
        world.setBlock(i + 1, j + 10, k + 10, stone);
        world.setBlock(i + 1, j + 10, k + 11, stone);
        world.setBlock(i + 1, j + 10, k + 12, stone);
        world.setBlock(i + 1, j + 10, k + 13, stair, 3, 2);
        world.setBlock(i + 1, j + 10, k + 17, glass);
        world.setBlock(i + 1, j + 11, k + 0, glass);
        world.setBlock(i + 1, j + 11, k + 5, stair, 2, 2);
        world.setBlock(i + 1, j + 11, k + 6, stone);
        world.setBlock(i + 1, j + 11, k + 7, stone);
        world.setBlock(i + 1, j + 11, k + 8, stone);
        world.setBlock(i + 1, j + 11, k + 9, stone);
        world.setBlock(i + 1, j + 11, k + 10, stone);
        world.setBlock(i + 1, j + 11, k + 11, stone);
        world.setBlock(i + 1, j + 11, k + 12, stair, 3, 2);
        world.setBlock(i + 1, j + 11, k + 17, glass);
        world.setBlock(i + 1, j + 12, k + 0, glass);
        world.setBlock(i + 1, j + 12, k + 6, stair, 2, 2);
        world.setBlock(i + 1, j + 12, k + 7, stone);
        world.setBlock(i + 1, j + 12, k + 8, stone);
        world.setBlock(i + 1, j + 12, k + 9, stone);
        world.setBlock(i + 1, j + 12, k + 10, stone);
        world.setBlock(i + 1, j + 12, k + 11, stair, 3, 2);
        world.setBlock(i + 1, j + 12, k + 17, glass);
        world.setBlock(i + 1, j + 13, k + 0, glass);
        world.setBlock(i + 1, j + 13, k + 7, stair, 2, 2);
        world.setBlock(i + 1, j + 13, k + 8, stone);
        world.setBlock(i + 1, j + 13, k + 9, stone);
        world.setBlock(i + 1, j + 13, k + 10, stair, 3, 2);
        world.setBlock(i + 1, j + 13, k + 17, glass);
        world.setBlock(i + 1, j + 14, k + 0, glass);
        world.setBlock(i + 1, j + 14, k + 1, carpet);
        world.setBlock(i + 1, j + 14, k + 2, carpet);
        world.setBlock(i + 1, j + 14, k + 3, carpet);
        world.setBlock(i + 1, j + 14, k + 14, carpet);
        world.setBlock(i + 1, j + 14, k + 15, carpet);
        world.setBlock(i + 1, j + 14, k + 16, carpet);
        world.setBlock(i + 1, j + 14, k + 17, glass);
        world.setBlock(i + 1, j + 15, k + 0, glass);
        world.setBlock(i + 1, j + 15, k + 1, carpet);
        world.setBlock(i + 1, j + 15, k + 2, carpet);
        world.setBlock(i + 1, j + 15, k + 3, carpet);
        world.setBlock(i + 1, j + 15, k + 4, carpet);
        world.setBlock(i + 1, j + 15, k + 13, carpet);
        world.setBlock(i + 1, j + 15, k + 14, carpet);
        world.setBlock(i + 1, j + 15, k + 15, carpet);
        world.setBlock(i + 1, j + 15, k + 16, carpet);
        world.setBlock(i + 1, j + 15, k + 17, glass);
        world.setBlock(i + 1, j + 16, k + 0, glass);
        world.setBlock(i + 1, j + 16, k + 1, Blocks.netherrack);
        world.setBlock(i + 1, j + 16, k + 2, stair, 3, 2);
        world.setBlock(i + 1, j + 16, k + 15, stair, 2, 2);
        world.setBlock(i + 1, j + 16, k + 16, Blocks.netherrack);
        world.setBlock(i + 1, j + 16, k + 17, glass);
        world.setBlock(i + 1, j + 17, k + 0, glass);
        world.setBlock(i + 1, j + 17, k + 1, (Block)Blocks.fire);
        world.setBlock(i + 1, j + 17, k + 16, (Block)Blocks.fire);
        world.setBlock(i + 1, j + 17, k + 17, glass);
        world.setBlock(i + 1, j + 18, k + 0, glass);
        world.setBlock(i + 1, j + 18, k + 17, glass);
        world.setBlock(i + 1, j + 19, k + 0, glass);
        world.setBlock(i + 1, j + 19, k + 17, glass);
        world.setBlock(i + 1, j + 20, k + 0, glass);
        world.setBlock(i + 1, j + 20, k + 17, glass);
        world.setBlock(i + 1, j + 21, k + 0, glass);
        world.setBlock(i + 1, j + 21, k + 1, stone);
        world.setBlock(i + 1, j + 21, k + 2, stone);
        world.setBlock(i + 1, j + 21, k + 3, stone);
        world.setBlock(i + 1, j + 21, k + 4, stone);
        world.setBlock(i + 1, j + 21, k + 5, stone);
        world.setBlock(i + 1, j + 21, k + 6, stone);
        world.setBlock(i + 1, j + 21, k + 7, stone);
        world.setBlock(i + 1, j + 21, k + 8, stone);
        world.setBlock(i + 1, j + 21, k + 9, stone);
        world.setBlock(i + 1, j + 21, k + 10, stone);
        world.setBlock(i + 1, j + 21, k + 11, stone);
        world.setBlock(i + 1, j + 21, k + 12, stone);
        world.setBlock(i + 1, j + 21, k + 13, stone);
        world.setBlock(i + 1, j + 21, k + 14, stone);
        world.setBlock(i + 1, j + 21, k + 15, stone);
        world.setBlock(i + 1, j + 21, k + 16, stone);
        world.setBlock(i + 1, j + 21, k + 17, glass);
        world.setBlock(i + 2, j + 0, k + 0, carpet);
        world.setBlock(i + 2, j + 0, k + 1, carpet);
        world.setBlock(i + 2, j + 0, k + 2, carpet);
        world.setBlock(i + 2, j + 0, k + 3, carpet);
        world.setBlock(i + 2, j + 0, k + 4, carpet);
        world.setBlock(i + 2, j + 0, k + 5, carpet);
        world.setBlock(i + 2, j + 0, k + 6, carpet);
        world.setBlock(i + 2, j + 0, k + 7, carpet);
        world.setBlock(i + 2, j + 0, k + 8, carpet);
        world.setBlock(i + 2, j + 0, k + 9, carpet);
        world.setBlock(i + 2, j + 0, k + 10, carpet);
        world.setBlock(i + 2, j + 0, k + 11, carpet);
        world.setBlock(i + 2, j + 0, k + 12, carpet);
        world.setBlock(i + 2, j + 0, k + 13, carpet);
        world.setBlock(i + 2, j + 0, k + 14, carpet);
        world.setBlock(i + 2, j + 0, k + 15, carpet);
        world.setBlock(i + 2, j + 0, k + 16, carpet);
        world.setBlock(i + 2, j + 0, k + 17, carpet);
        world.setBlock(i + 2, j + 1, k + 0, glass);
        world.setBlock(i + 2, j + 1, k + 4, slab, 11, 2);
        world.setBlock(i + 2, j + 1, k + 13, slab, 11, 2);
        world.setBlock(i + 2, j + 1, k + 17, glass);
        world.setBlock(i + 2, j + 2, k + 0, glass);
        world.setBlock(i + 2, j + 2, k + 17, glass);
        world.setBlock(i + 2, j + 3, k + 0, glass);
        world.setBlock(i + 2, j + 3, k + 17, glass);
        world.setBlock(i + 2, j + 4, k + 0, glass);
        world.setBlock(i + 2, j + 4, k + 17, glass);
        world.setBlock(i + 2, j + 5, k + 0, glass);
        world.setBlock(i + 2, j + 5, k + 2, lamp);
        world.setBlock(i + 2, j + 5, k + 15, lamp);
        world.setBlock(i + 2, j + 5, k + 17, glass);
        world.setBlock(i + 2, j + 6, k + 0, glass);
        world.setBlock(i + 2, j + 6, k + 2, fence);
        world.setBlock(i + 2, j + 6, k + 15, fence);
        world.setBlock(i + 2, j + 6, k + 17, glass);
        world.setBlock(i + 2, j + 7, k + 0, glass);
        world.setBlock(i + 2, j + 7, k + 1, carpet);
        world.setBlock(i + 2, j + 7, k + 2, carpet);
        world.setBlock(i + 2, j + 7, k + 3, carpet);
        world.setBlock(i + 2, j + 7, k + 4, carpet);
        world.setBlock(i + 2, j + 7, k + 5, carpet);
        world.setBlock(i + 2, j + 7, k + 6, carpet);
        world.setBlock(i + 2, j + 7, k + 7, carpet);
        world.setBlock(i + 2, j + 7, k + 8, carpet);
        world.setBlock(i + 2, j + 7, k + 9, carpet);
        world.setBlock(i + 2, j + 7, k + 10, carpet);
        world.setBlock(i + 2, j + 7, k + 11, carpet);
        world.setBlock(i + 2, j + 7, k + 12, carpet);
        world.setBlock(i + 2, j + 7, k + 13, carpet);
        world.setBlock(i + 2, j + 7, k + 14, carpet);
        world.setBlock(i + 2, j + 7, k + 15, carpet);
        world.setBlock(i + 2, j + 7, k + 16, carpet);
        world.setBlock(i + 2, j + 7, k + 17, glass);
        world.setBlock(i + 2, j + 8, k + 0, glass);
        world.setBlock(i + 2, j + 8, k + 1, carpet);
        world.setBlock(i + 2, j + 8, k + 2, carpet);
        world.setBlock(i + 2, j + 8, k + 3, carpet);
        world.setBlock(i + 2, j + 8, k + 4, carpet);
        world.setBlock(i + 2, j + 8, k + 5, carpet);
        world.setBlock(i + 2, j + 8, k + 6, carpet);
        world.setBlock(i + 2, j + 8, k + 7, carpet);
        world.setBlock(i + 2, j + 8, k + 8, carpet);
        world.setBlock(i + 2, j + 8, k + 9, carpet);
        world.setBlock(i + 2, j + 8, k + 10, carpet);
        world.setBlock(i + 2, j + 8, k + 11, carpet);
        world.setBlock(i + 2, j + 8, k + 12, carpet);
        world.setBlock(i + 2, j + 8, k + 13, carpet);
        world.setBlock(i + 2, j + 8, k + 14, carpet);
        world.setBlock(i + 2, j + 8, k + 15, carpet);
        world.setBlock(i + 2, j + 8, k + 16, carpet);
        world.setBlock(i + 2, j + 8, k + 17, glass);
        world.setBlock(i + 2, j + 9, k + 0, glass);
        world.setBlock(i + 2, j + 9, k + 3, stair, 2, 2);
        world.setBlock(i + 2, j + 9, k + 4, stone);
        world.setBlock(i + 2, j + 9, k + 5, stone);
        world.setBlock(i + 2, j + 9, k + 6, stone);
        world.setBlock(i + 2, j + 9, k + 7, stone);
        world.setBlock(i + 2, j + 9, k + 8, stone);
        world.setBlock(i + 2, j + 9, k + 9, stone);
        world.setBlock(i + 2, j + 9, k + 10, stone);
        world.setBlock(i + 2, j + 9, k + 11, stone);
        world.setBlock(i + 2, j + 9, k + 12, stone);
        world.setBlock(i + 2, j + 9, k + 13, stone);
        world.setBlock(i + 2, j + 9, k + 14, stair, 3, 2);
        world.setBlock(i + 2, j + 9, k + 17, glass);
        world.setBlock(i + 2, j + 10, k + 0, glass);
        world.setBlock(i + 2, j + 10, k + 4, stair, 2, 2);
        world.setBlock(i + 2, j + 10, k + 5, stone);
        world.setBlock(i + 2, j + 10, k + 6, stone);
        world.setBlock(i + 2, j + 10, k + 7, stone);
        world.setBlock(i + 2, j + 10, k + 8, stone);
        world.setBlock(i + 2, j + 10, k + 9, stone);
        world.setBlock(i + 2, j + 10, k + 10, stone);
        world.setBlock(i + 2, j + 10, k + 11, stone);
        world.setBlock(i + 2, j + 10, k + 12, stone);
        world.setBlock(i + 2, j + 10, k + 13, stair, 3, 2);
        world.setBlock(i + 2, j + 10, k + 17, glass);
        world.setBlock(i + 2, j + 11, k + 0, glass);
        world.setBlock(i + 2, j + 11, k + 5, stair, 2, 2);
        world.setBlock(i + 2, j + 11, k + 6, stone);
        world.setBlock(i + 2, j + 11, k + 7, stone);
        world.setBlock(i + 2, j + 11, k + 8, stone);
        world.setBlock(i + 2, j + 11, k + 9, stone);
        world.setBlock(i + 2, j + 11, k + 10, stone);
        world.setBlock(i + 2, j + 11, k + 11, stone);
        world.setBlock(i + 2, j + 11, k + 12, stair, 3, 2);
        world.setBlock(i + 2, j + 11, k + 17, glass);
        world.setBlock(i + 2, j + 12, k + 0, glass);
        world.setBlock(i + 2, j + 12, k + 6, stair, 2, 2);
        world.setBlock(i + 2, j + 12, k + 7, stone);
        world.setBlock(i + 2, j + 12, k + 8, stone);
        world.setBlock(i + 2, j + 12, k + 9, stone);
        world.setBlock(i + 2, j + 12, k + 10, stone);
        world.setBlock(i + 2, j + 12, k + 11, stair, 3, 2);
        world.setBlock(i + 2, j + 12, k + 17, glass);
        world.setBlock(i + 2, j + 13, k + 0, glass);
        world.setBlock(i + 2, j + 13, k + 7, stair, 2, 2);
        world.setBlock(i + 2, j + 13, k + 8, stone);
        world.setBlock(i + 2, j + 13, k + 9, stone);
        world.setBlock(i + 2, j + 13, k + 10, stair, 3, 2);
        world.setBlock(i + 2, j + 13, k + 17, glass);
        world.setBlock(i + 2, j + 14, k + 0, glass);
        world.setBlock(i + 2, j + 14, k + 1, carpet);
        world.setBlock(i + 2, j + 14, k + 2, carpet);
        world.setBlock(i + 2, j + 14, k + 3, carpet);
        world.setBlock(i + 2, j + 14, k + 14, carpet);
        world.setBlock(i + 2, j + 14, k + 15, carpet);
        world.setBlock(i + 2, j + 14, k + 16, carpet);
        world.setBlock(i + 2, j + 14, k + 17, glass);
        world.setBlock(i + 2, j + 15, k + 0, glass);
        world.setBlock(i + 2, j + 15, k + 1, carpet);
        world.setBlock(i + 2, j + 15, k + 2, carpet);
        world.setBlock(i + 2, j + 15, k + 3, carpet);
        world.setBlock(i + 2, j + 15, k + 4, carpet);
        world.setBlock(i + 2, j + 15, k + 13, carpet);
        world.setBlock(i + 2, j + 15, k + 14, carpet);
        world.setBlock(i + 2, j + 15, k + 15, carpet);
        world.setBlock(i + 2, j + 15, k + 16, carpet);
        world.setBlock(i + 2, j + 15, k + 17, glass);
        world.setBlock(i + 2, j + 16, k + 0, glass);
        world.setBlock(i + 2, j + 16, k + 1, stair, 1, 2);
        world.setBlock(i + 2, j + 16, k + 2, stair, 3, 2);
        world.setBlock(i + 2, j + 16, k + 15, stair, 2, 2);
        world.setBlock(i + 2, j + 16, k + 16, stair, 1, 2);
        world.setBlock(i + 2, j + 16, k + 17, glass);
        world.setBlock(i + 2, j + 17, k + 0, glass);
        world.setBlock(i + 2, j + 17, k + 17, glass);
        world.setBlock(i + 2, j + 18, k + 0, glass);
        world.setBlock(i + 2, j + 18, k + 17, glass);
        world.setBlock(i + 2, j + 19, k + 0, glass);
        world.setBlock(i + 2, j + 19, k + 2, lamp);
        world.setBlock(i + 2, j + 19, k + 15, lamp);
        world.setBlock(i + 2, j + 19, k + 17, glass);
        world.setBlock(i + 2, j + 20, k + 0, glass);
        world.setBlock(i + 2, j + 20, k + 17, glass);
        world.setBlock(i + 2, j + 21, k + 0, glass);
        world.setBlock(i + 2, j + 21, k + 1, stone);
        world.setBlock(i + 2, j + 21, k + 2, stone);
        world.setBlock(i + 2, j + 21, k + 3, stone);
        world.setBlock(i + 2, j + 21, k + 4, stone);
        world.setBlock(i + 2, j + 21, k + 5, stone);
        world.setBlock(i + 2, j + 21, k + 6, stone);
        world.setBlock(i + 2, j + 21, k + 7, stone);
        world.setBlock(i + 2, j + 21, k + 8, stone);
        world.setBlock(i + 2, j + 21, k + 9, stone);
        world.setBlock(i + 2, j + 21, k + 10, stone);
        world.setBlock(i + 2, j + 21, k + 11, stone);
        world.setBlock(i + 2, j + 21, k + 12, stone);
        world.setBlock(i + 2, j + 21, k + 13, stone);
        world.setBlock(i + 2, j + 21, k + 14, stone);
        world.setBlock(i + 2, j + 21, k + 15, stone);
        world.setBlock(i + 2, j + 21, k + 16, stone);
        world.setBlock(i + 2, j + 21, k + 17, glass);
        world.setBlock(i + 3, j + 0, k + 0, carpet);
        world.setBlock(i + 3, j + 0, k + 1, carpet);
        world.setBlock(i + 3, j + 0, k + 2, carpet);
        world.setBlock(i + 3, j + 0, k + 3, carpet);
        world.setBlock(i + 3, j + 0, k + 4, carpet);
        world.setBlock(i + 3, j + 0, k + 5, carpet);
        world.setBlock(i + 3, j + 0, k + 6, carpet);
        world.setBlock(i + 3, j + 0, k + 7, carpet);
        world.setBlock(i + 3, j + 0, k + 8, carpet);
        world.setBlock(i + 3, j + 0, k + 9, carpet);
        world.setBlock(i + 3, j + 0, k + 10, carpet);
        world.setBlock(i + 3, j + 0, k + 11, carpet);
        world.setBlock(i + 3, j + 0, k + 12, carpet);
        world.setBlock(i + 3, j + 0, k + 13, carpet);
        world.setBlock(i + 3, j + 0, k + 14, carpet);
        world.setBlock(i + 3, j + 0, k + 15, carpet);
        world.setBlock(i + 3, j + 0, k + 16, carpet);
        world.setBlock(i + 3, j + 0, k + 17, carpet);
        world.setBlock(i + 3, j + 1, k + 0, glass);
        world.setBlock(i + 3, j + 1, k + 4, slab, 11, 2);
        world.setBlock(i + 3, j + 1, k + 13, slab, 11, 2);
        world.setBlock(i + 3, j + 1, k + 17, glass);
        world.setBlock(i + 3, j + 2, k + 0, glass);
        world.setBlock(i + 3, j + 2, k + 17, glass);
        world.setBlock(i + 3, j + 3, k + 0, glass);
        world.setBlock(i + 3, j + 3, k + 17, glass);
        world.setBlock(i + 3, j + 4, k + 0, glass);
        world.setBlock(i + 3, j + 4, k + 17, glass);
        world.setBlock(i + 3, j + 5, k + 0, glass);
        world.setBlock(i + 3, j + 5, k + 8, lamp);
        world.setBlock(i + 3, j + 5, k + 9, lamp);
        world.setBlock(i + 3, j + 5, k + 17, glass);
        world.setBlock(i + 3, j + 6, k + 0, glass);
        world.setBlock(i + 3, j + 6, k + 17, glass);
        world.setBlock(i + 3, j + 7, k + 0, glass);
        world.setBlock(i + 3, j + 7, k + 1, carpet);
        world.setBlock(i + 3, j + 7, k + 2, carpet);
        world.setBlock(i + 3, j + 7, k + 3, carpet);
        world.setBlock(i + 3, j + 7, k + 4, carpet);
        world.setBlock(i + 3, j + 7, k + 5, carpet);
        world.setBlock(i + 3, j + 7, k + 6, carpet);
        world.setBlock(i + 3, j + 7, k + 7, carpet);
        world.setBlock(i + 3, j + 7, k + 8, carpet);
        world.setBlock(i + 3, j + 7, k + 9, carpet);
        world.setBlock(i + 3, j + 7, k + 10, carpet);
        world.setBlock(i + 3, j + 7, k + 11, carpet);
        world.setBlock(i + 3, j + 7, k + 12, carpet);
        world.setBlock(i + 3, j + 7, k + 13, carpet);
        world.setBlock(i + 3, j + 7, k + 14, carpet);
        world.setBlock(i + 3, j + 7, k + 15, carpet);
        world.setBlock(i + 3, j + 7, k + 16, carpet);
        world.setBlock(i + 3, j + 7, k + 17, glass);
        world.setBlock(i + 3, j + 8, k + 0, glass);
        world.setBlock(i + 3, j + 8, k + 1, carpet);
        world.setBlock(i + 3, j + 8, k + 2, carpet);
        world.setBlock(i + 3, j + 8, k + 3, carpet);
        world.setBlock(i + 3, j + 8, k + 4, carpet);
        world.setBlock(i + 3, j + 8, k + 5, carpet);
        world.setBlock(i + 3, j + 8, k + 6, carpet);
        world.setBlock(i + 3, j + 8, k + 7, carpet);
        world.setBlock(i + 3, j + 8, k + 8, Blocks.netherrack);
        world.setBlock(i + 3, j + 8, k + 9, Blocks.netherrack);
        world.setBlock(i + 3, j + 8, k + 10, carpet);
        world.setBlock(i + 3, j + 8, k + 11, carpet);
        world.setBlock(i + 3, j + 8, k + 12, carpet);
        world.setBlock(i + 3, j + 8, k + 13, carpet);
        world.setBlock(i + 3, j + 8, k + 14, carpet);
        world.setBlock(i + 3, j + 8, k + 15, carpet);
        world.setBlock(i + 3, j + 8, k + 16, carpet);
        world.setBlock(i + 3, j + 8, k + 17, glass);
        world.setBlock(i + 3, j + 9, k + 0, glass);
        world.setBlock(i + 3, j + 9, k + 3, glass);
        world.setBlock(i + 3, j + 9, k + 4, glass);
        world.setBlock(i + 3, j + 9, k + 5, glass);
        world.setBlock(i + 3, j + 9, k + 6, glass);
        world.setBlock(i + 3, j + 9, k + 7, stone);
        world.setBlock(i + 3, j + 9, k + 8, (Block)Blocks.fire);
        world.setBlock(i + 3, j + 9, k + 9, (Block)Blocks.fire);
        world.setBlock(i + 3, j + 9, k + 10, stone);
        world.setBlock(i + 3, j + 9, k + 11, glass);
        world.setBlock(i + 3, j + 9, k + 12, glass);
        world.setBlock(i + 3, j + 9, k + 13, glass);
        world.setBlock(i + 3, j + 9, k + 14, glass);
        world.setBlock(i + 3, j + 9, k + 17, glass);
        world.setBlock(i + 3, j + 10, k + 0, glass);
        world.setBlock(i + 3, j + 10, k + 3, glass);
        world.setBlock(i + 3, j + 10, k + 4, glass);
        world.setBlock(i + 3, j + 10, k + 5, glass);
        world.setBlock(i + 3, j + 10, k + 6, glass);
        world.setBlock(i + 3, j + 10, k + 7, stone);
        world.setBlock(i + 3, j + 10, k + 10, stone);
        world.setBlock(i + 3, j + 10, k + 11, glass);
        world.setBlock(i + 3, j + 10, k + 12, glass);
        world.setBlock(i + 3, j + 10, k + 13, glass);
        world.setBlock(i + 3, j + 10, k + 14, glass);
        world.setBlock(i + 3, j + 10, k + 17, glass);
        world.setBlock(i + 3, j + 11, k + 0, glass);
        world.setBlock(i + 3, j + 11, k + 1, glass);
        world.setBlock(i + 3, j + 11, k + 2, glass);
        world.setBlock(i + 3, j + 11, k + 3, glass);
        world.setBlock(i + 3, j + 11, k + 4, glass);
        world.setBlock(i + 3, j + 11, k + 5, glass);
        world.setBlock(i + 3, j + 11, k + 6, glass);
        world.setBlock(i + 3, j + 11, k + 7, glass);
        world.setBlock(i + 3, j + 11, k + 8, stone);
        world.setBlock(i + 3, j + 11, k + 9, stone);
        world.setBlock(i + 3, j + 11, k + 10, glass);
        world.setBlock(i + 3, j + 11, k + 11, glass);
        world.setBlock(i + 3, j + 11, k + 12, glass);
        world.setBlock(i + 3, j + 11, k + 13, glass);
        world.setBlock(i + 3, j + 11, k + 14, glass);
        world.setBlock(i + 3, j + 11, k + 15, glass);
        world.setBlock(i + 3, j + 11, k + 16, glass);
        world.setBlock(i + 3, j + 11, k + 17, glass);
        world.setBlock(i + 3, j + 12, k + 0, glass);
        world.setBlock(i + 3, j + 12, k + 1, glass);
        world.setBlock(i + 3, j + 12, k + 2, glass);
        world.setBlock(i + 3, j + 12, k + 3, glass);
        world.setBlock(i + 3, j + 12, k + 4, glass);
        world.setBlock(i + 3, j + 12, k + 5, glass);
        world.setBlock(i + 3, j + 12, k + 6, glass);
        world.setBlock(i + 3, j + 12, k + 7, glass);
        world.setBlock(i + 3, j + 12, k + 8, stone);
        world.setBlock(i + 3, j + 12, k + 9, stone);
        world.setBlock(i + 3, j + 12, k + 10, glass);
        world.setBlock(i + 3, j + 12, k + 11, glass);
        world.setBlock(i + 3, j + 12, k + 12, glass);
        world.setBlock(i + 3, j + 12, k + 13, glass);
        world.setBlock(i + 3, j + 12, k + 14, glass);
        world.setBlock(i + 3, j + 12, k + 15, glass);
        world.setBlock(i + 3, j + 12, k + 16, glass);
        world.setBlock(i + 3, j + 12, k + 17, glass);
        world.setBlock(i + 3, j + 13, k + 0, glass);
        world.setBlock(i + 3, j + 13, k + 1, glass);
        world.setBlock(i + 3, j + 13, k + 2, glass);
        world.setBlock(i + 3, j + 13, k + 3, glass);
        world.setBlock(i + 3, j + 13, k + 4, glass);
        world.setBlock(i + 3, j + 13, k + 5, glass);
        world.setBlock(i + 3, j + 13, k + 6, glass);
        world.setBlock(i + 3, j + 13, k + 7, glass);
        world.setBlock(i + 3, j + 13, k + 8, stone);
        world.setBlock(i + 3, j + 13, k + 9, stone);
        world.setBlock(i + 3, j + 13, k + 10, glass);
        world.setBlock(i + 3, j + 13, k + 11, glass);
        world.setBlock(i + 3, j + 13, k + 12, glass);
        world.setBlock(i + 3, j + 13, k + 13, glass);
        world.setBlock(i + 3, j + 13, k + 14, glass);
        world.setBlock(i + 3, j + 13, k + 15, glass);
        world.setBlock(i + 3, j + 13, k + 16, glass);
        world.setBlock(i + 3, j + 13, k + 17, glass);
        world.setBlock(i + 3, j + 14, k + 0, glass);
        world.setBlock(i + 3, j + 14, k + 1, carpet);
        world.setBlock(i + 3, j + 14, k + 2, carpet);
        world.setBlock(i + 3, j + 14, k + 3, carpet);
        world.setBlock(i + 3, j + 14, k + 4, carpet);
        world.setBlock(i + 3, j + 14, k + 5, carpet);
        world.setBlock(i + 3, j + 14, k + 6, carpet);
        world.setBlock(i + 3, j + 14, k + 7, lamp);
        world.setBlock(i + 3, j + 14, k + 8, stair);
        world.setBlock(i + 3, j + 14, k + 9, stair);
        world.setBlock(i + 3, j + 14, k + 10, lamp);
        world.setBlock(i + 3, j + 14, k + 11, carpet);
        world.setBlock(i + 3, j + 14, k + 12, carpet);
        world.setBlock(i + 3, j + 14, k + 13, carpet);
        world.setBlock(i + 3, j + 14, k + 14, carpet);
        world.setBlock(i + 3, j + 14, k + 15, carpet);
        world.setBlock(i + 3, j + 14, k + 16, carpet);
        world.setBlock(i + 3, j + 14, k + 17, glass);
        world.setBlock(i + 3, j + 15, k + 0, glass);
        world.setBlock(i + 3, j + 15, k + 1, carpet);
        world.setBlock(i + 3, j + 15, k + 2, carpet);
        world.setBlock(i + 3, j + 15, k + 3, carpet);
        world.setBlock(i + 3, j + 15, k + 4, carpet);
        world.setBlock(i + 3, j + 15, k + 5, carpet);
        world.setBlock(i + 3, j + 15, k + 6, carpet);
        world.setBlock(i + 3, j + 15, k + 7, lamp);
        world.setBlock(i + 3, j + 15, k + 10, lamp);
        world.setBlock(i + 3, j + 15, k + 11, carpet);
        world.setBlock(i + 3, j + 15, k + 12, carpet);
        world.setBlock(i + 3, j + 15, k + 13, carpet);
        world.setBlock(i + 3, j + 15, k + 14, carpet);
        world.setBlock(i + 3, j + 15, k + 15, carpet);
        world.setBlock(i + 3, j + 15, k + 16, carpet);
        world.setBlock(i + 3, j + 15, k + 17, glass);
        world.setBlock(i + 3, j + 16, k + 0, glass);
        world.setBlock(i + 3, j + 16, k + 17, glass);
        world.setBlock(i + 3, j + 17, k + 0, glass);
        world.setBlock(i + 3, j + 17, k + 17, glass);
        world.setBlock(i + 3, j + 18, k + 0, glass);
        world.setBlock(i + 3, j + 18, k + 17, glass);
        world.setBlock(i + 3, j + 19, k + 0, glass);
        world.setBlock(i + 3, j + 19, k + 17, glass);
        world.setBlock(i + 3, j + 20, k + 0, glass);
        world.setBlock(i + 3, j + 20, k + 17, glass);
        world.setBlock(i + 3, j + 21, k + 0, glass);
        world.setBlock(i + 3, j + 21, k + 1, stone);
        world.setBlock(i + 3, j + 21, k + 2, stone);
        world.setBlock(i + 3, j + 21, k + 3, stone);
        world.setBlock(i + 3, j + 21, k + 4, stone);
        world.setBlock(i + 3, j + 21, k + 5, stone);
        world.setBlock(i + 3, j + 21, k + 6, stone);
        world.setBlock(i + 3, j + 21, k + 7, lamp);
        world.setBlock(i + 3, j + 21, k + 8, lamp);
        world.setBlock(i + 3, j + 21, k + 9, lamp);
        world.setBlock(i + 3, j + 21, k + 10, lamp);
        world.setBlock(i + 3, j + 21, k + 11, stone);
        world.setBlock(i + 3, j + 21, k + 12, stone);
        world.setBlock(i + 3, j + 21, k + 13, stone);
        world.setBlock(i + 3, j + 21, k + 14, stone);
        world.setBlock(i + 3, j + 21, k + 15, stone);
        world.setBlock(i + 3, j + 21, k + 16, stone);
        world.setBlock(i + 3, j + 21, k + 17, glass);
        world.setBlock(i + 4, j + 0, k + 0, carpet);
        world.setBlock(i + 4, j + 0, k + 1, carpet);
        world.setBlock(i + 4, j + 0, k + 2, carpet);
        world.setBlock(i + 4, j + 0, k + 3, carpet);
        world.setBlock(i + 4, j + 0, k + 4, carpet);
        world.setBlock(i + 4, j + 0, k + 5, carpet);
        world.setBlock(i + 4, j + 0, k + 6, carpet);
        world.setBlock(i + 4, j + 0, k + 7, carpet);
        world.setBlock(i + 4, j + 0, k + 8, carpet);
        world.setBlock(i + 4, j + 0, k + 9, carpet);
        world.setBlock(i + 4, j + 0, k + 10, carpet);
        world.setBlock(i + 4, j + 0, k + 11, carpet);
        world.setBlock(i + 4, j + 0, k + 12, carpet);
        world.setBlock(i + 4, j + 0, k + 13, carpet);
        world.setBlock(i + 4, j + 0, k + 14, carpet);
        world.setBlock(i + 4, j + 0, k + 15, carpet);
        world.setBlock(i + 4, j + 0, k + 16, carpet);
        world.setBlock(i + 4, j + 0, k + 17, carpet);
        world.setBlock(i + 4, j + 1, k + 0, glass);
        world.setBlock(i + 4, j + 1, k + 1, slab, 11, 2);
        world.setBlock(i + 4, j + 1, k + 2, slab, 11, 2);
        world.setBlock(i + 4, j + 1, k + 3, slab, 11, 2);
        world.setBlock(i + 4, j + 1, k + 4, stone);
        world.setBlock(i + 4, j + 1, k + 13, stone);
        world.setBlock(i + 4, j + 1, k + 14, slab, 11, 2);
        world.setBlock(i + 4, j + 1, k + 15, slab, 11, 2);
        world.setBlock(i + 4, j + 1, k + 16, slab, 11, 2);
        world.setBlock(i + 4, j + 1, k + 17, glass);
        world.setBlock(i + 4, j + 2, k + 0, glass);
        world.setBlock(i + 4, j + 2, k + 4, fence);
        world.setBlock(i + 4, j + 2, k + 13, fence);
        world.setBlock(i + 4, j + 2, k + 17, glass);
        world.setBlock(i + 4, j + 3, k + 0, glass);
        world.setBlock(i + 4, j + 3, k + 4, fence);
        world.setBlock(i + 4, j + 3, k + 13, fence);
        world.setBlock(i + 4, j + 3, k + 17, glass);
        world.setBlock(i + 4, j + 4, k + 0, glass);
        world.setBlock(i + 4, j + 4, k + 4, fence);
        world.setBlock(i + 4, j + 4, k + 8, lamp);
        world.setBlock(i + 4, j + 4, k + 9, lamp);
        world.setBlock(i + 4, j + 4, k + 13, fence);
        world.setBlock(i + 4, j + 4, k + 17, glass);
        world.setBlock(i + 4, j + 5, k + 0, glass);
        world.setBlock(i + 4, j + 5, k + 4, fence);
        world.setBlock(i + 4, j + 5, k + 7, lamp);
        world.setBlock(i + 4, j + 5, k + 8, fence);
        world.setBlock(i + 4, j + 5, k + 9, fence);
        world.setBlock(i + 4, j + 5, k + 10, lamp);
        world.setBlock(i + 4, j + 5, k + 13, fence);
        world.setBlock(i + 4, j + 5, k + 17, glass);
        world.setBlock(i + 4, j + 6, k + 0, glass);
        world.setBlock(i + 4, j + 6, k + 4, fence);
        world.setBlock(i + 4, j + 6, k + 8, fence);
        world.setBlock(i + 4, j + 6, k + 9, fence);
        world.setBlock(i + 4, j + 6, k + 13, fence);
        world.setBlock(i + 4, j + 6, k + 17, glass);
        world.setBlock(i + 4, j + 7, k + 0, glass);
        world.setBlock(i + 4, j + 7, k + 1, carpet);
        world.setBlock(i + 4, j + 7, k + 2, carpet);
        world.setBlock(i + 4, j + 7, k + 3, carpet);
        world.setBlock(i + 4, j + 7, k + 4, carpet);
        world.setBlock(i + 4, j + 7, k + 5, carpet);
        world.setBlock(i + 4, j + 7, k + 6, carpet);
        world.setBlock(i + 4, j + 7, k + 7, carpet);
        world.setBlock(i + 4, j + 7, k + 8, carpet);
        world.setBlock(i + 4, j + 7, k + 9, carpet);
        world.setBlock(i + 4, j + 7, k + 10, carpet);
        world.setBlock(i + 4, j + 7, k + 11, carpet);
        world.setBlock(i + 4, j + 7, k + 12, carpet);
        world.setBlock(i + 4, j + 7, k + 13, carpet);
        world.setBlock(i + 4, j + 7, k + 14, carpet);
        world.setBlock(i + 4, j + 7, k + 15, carpet);
        world.setBlock(i + 4, j + 7, k + 16, carpet);
        world.setBlock(i + 4, j + 7, k + 17, glass);
        world.setBlock(i + 4, j + 8, k + 0, glass);
        world.setBlock(i + 4, j + 8, k + 1, carpet);
        world.setBlock(i + 4, j + 8, k + 2, carpet);
        world.setBlock(i + 4, j + 8, k + 3, carpet);
        world.setBlock(i + 4, j + 8, k + 4, carpet);
        world.setBlock(i + 4, j + 8, k + 5, carpet);
        world.setBlock(i + 4, j + 8, k + 6, carpet);
        world.setBlock(i + 4, j + 8, k + 7, carpet);
        world.setBlock(i + 4, j + 8, k + 8, carpet);
        world.setBlock(i + 4, j + 8, k + 9, carpet);
        world.setBlock(i + 4, j + 8, k + 10, carpet);
        world.setBlock(i + 4, j + 8, k + 11, carpet);
        world.setBlock(i + 4, j + 8, k + 12, carpet);
        world.setBlock(i + 4, j + 8, k + 13, carpet);
        world.setBlock(i + 4, j + 8, k + 14, carpet);
        world.setBlock(i + 4, j + 8, k + 15, carpet);
        world.setBlock(i + 4, j + 8, k + 16, carpet);
        world.setBlock(i + 4, j + 8, k + 17, glass);
        world.setBlock(i + 4, j + 9, k + 0, glass);
        world.setBlock(i + 4, j + 9, k + 6, stair, 2, 2);
        world.setBlock(i + 4, j + 9, k + 7, stone);
        world.setBlock(i + 4, j + 9, k + 8, slab, 3, 2);
        world.setBlock(i + 4, j + 9, k + 9, slab, 3, 2);
        world.setBlock(i + 4, j + 9, k + 10, stone);
        world.setBlock(i + 4, j + 9, k + 11, stair, 3, 2);
        world.setBlock(i + 4, j + 9, k + 17, glass);
        world.setBlock(i + 4, j + 10, k + 0, glass);
        world.setBlock(i + 4, j + 10, k + 7, stone);
        world.setBlock(i + 4, j + 10, k + 10, stone);
        world.setBlock(i + 4, j + 10, k + 17, glass);
        world.setBlock(i + 4, j + 11, k + 0, glass);
        world.setBlock(i + 4, j + 11, k + 7, stone);
        world.setBlock(i + 4, j + 11, k + 8, stair, 5, 2);
        world.setBlock(i + 4, j + 11, k + 9, stair, 5, 2);
        world.setBlock(i + 4, j + 11, k + 10, stone);
        world.setBlock(i + 4, j + 11, k + 17, glass);
        world.setBlock(i + 4, j + 12, k + 0, glass);
        world.setBlock(i + 4, j + 12, k + 7, stone);
        world.setBlock(i + 4, j + 12, k + 8, stone);
        world.setBlock(i + 4, j + 12, k + 9, stone);
        world.setBlock(i + 4, j + 12, k + 10, stone);
        world.setBlock(i + 4, j + 12, k + 17, glass);
        world.setBlock(i + 4, j + 13, k + 0, glass);
        world.setBlock(i + 4, j + 13, k + 7, stone);
        world.setBlock(i + 4, j + 13, k + 8, stone);
        world.setBlock(i + 4, j + 13, k + 9, stone);
        world.setBlock(i + 4, j + 13, k + 10, stone);
        world.setBlock(i + 4, j + 13, k + 17, glass);
        world.setBlock(i + 4, j + 14, k + 0, glass);
        world.setBlock(i + 4, j + 14, k + 1, carpet);
        world.setBlock(i + 4, j + 14, k + 2, carpet);
        world.setBlock(i + 4, j + 14, k + 3, carpet);
        world.setBlock(i + 4, j + 14, k + 4, carpet);
        world.setBlock(i + 4, j + 14, k + 5, carpet);
        world.setBlock(i + 4, j + 14, k + 6, carpet);
        world.setBlock(i + 4, j + 14, k + 7, carpet);
        world.setBlock(i + 4, j + 14, k + 8, carpet);
        world.setBlock(i + 4, j + 14, k + 9, carpet);
        world.setBlock(i + 4, j + 14, k + 10, carpet);
        world.setBlock(i + 4, j + 14, k + 11, carpet);
        world.setBlock(i + 4, j + 14, k + 12, carpet);
        world.setBlock(i + 4, j + 14, k + 13, carpet);
        world.setBlock(i + 4, j + 14, k + 14, carpet);
        world.setBlock(i + 4, j + 14, k + 15, carpet);
        world.setBlock(i + 4, j + 14, k + 16, carpet);
        world.setBlock(i + 4, j + 14, k + 17, glass);
        world.setBlock(i + 4, j + 15, k + 0, glass);
        world.setBlock(i + 4, j + 15, k + 1, carpet);
        world.setBlock(i + 4, j + 15, k + 2, carpet);
        world.setBlock(i + 4, j + 15, k + 3, carpet);
        world.setBlock(i + 4, j + 15, k + 4, carpet);
        world.setBlock(i + 4, j + 15, k + 5, carpet);
        world.setBlock(i + 4, j + 15, k + 6, carpet);
        world.setBlock(i + 4, j + 15, k + 7, carpet);
        world.setBlock(i + 4, j + 15, k + 8, stair);
        world.setBlock(i + 4, j + 15, k + 9, stair);
        world.setBlock(i + 4, j + 15, k + 10, carpet);
        world.setBlock(i + 4, j + 15, k + 11, carpet);
        world.setBlock(i + 4, j + 15, k + 12, carpet);
        world.setBlock(i + 4, j + 15, k + 13, carpet);
        world.setBlock(i + 4, j + 15, k + 14, carpet);
        world.setBlock(i + 4, j + 15, k + 15, carpet);
        world.setBlock(i + 4, j + 15, k + 16, carpet);
        world.setBlock(i + 4, j + 15, k + 17, glass);
        world.setBlock(i + 4, j + 16, k + 0, glass);
        world.setBlock(i + 4, j + 16, k + 17, glass);
        world.setBlock(i + 4, j + 17, k + 0, glass);
        world.setBlock(i + 4, j + 17, k + 17, glass);
        world.setBlock(i + 4, j + 18, k + 0, glass);
        world.setBlock(i + 4, j + 18, k + 17, glass);
        world.setBlock(i + 4, j + 19, k + 0, glass);
        world.setBlock(i + 4, j + 19, k + 17, glass);
        world.setBlock(i + 4, j + 20, k + 0, glass);
        world.setBlock(i + 4, j + 20, k + 17, glass);
        world.setBlock(i + 4, j + 21, k + 0, glass);
        world.setBlock(i + 4, j + 21, k + 1, stone);
        world.setBlock(i + 4, j + 21, k + 2, stone);
        world.setBlock(i + 4, j + 21, k + 3, stone);
        world.setBlock(i + 4, j + 21, k + 4, stone);
        world.setBlock(i + 4, j + 21, k + 5, stone);
        world.setBlock(i + 4, j + 21, k + 6, lamp);
        world.setBlock(i + 4, j + 21, k + 7, stone);
        world.setBlock(i + 4, j + 21, k + 8, stone);
        world.setBlock(i + 4, j + 21, k + 9, stone);
        world.setBlock(i + 4, j + 21, k + 10, stone);
        world.setBlock(i + 4, j + 21, k + 11, stone);
        world.setBlock(i + 4, j + 21, k + 12, stone);
        world.setBlock(i + 4, j + 21, k + 13, stone);
        world.setBlock(i + 4, j + 21, k + 14, stone);
        world.setBlock(i + 4, j + 21, k + 15, stone);
        world.setBlock(i + 4, j + 21, k + 16, stone);
        world.setBlock(i + 4, j + 21, k + 17, glass);
        world.setBlock(i + 5, j + 0, k + 0, carpet);
        world.setBlock(i + 5, j + 0, k + 1, carpet);
        world.setBlock(i + 5, j + 0, k + 2, carpet);
        world.setBlock(i + 5, j + 0, k + 3, carpet);
        world.setBlock(i + 5, j + 0, k + 4, carpet);
        world.setBlock(i + 5, j + 0, k + 5, carpet);
        world.setBlock(i + 5, j + 0, k + 6, carpet);
        world.setBlock(i + 5, j + 0, k + 7, carpet);
        world.setBlock(i + 5, j + 0, k + 8, carpet);
        world.setBlock(i + 5, j + 0, k + 9, carpet);
        world.setBlock(i + 5, j + 0, k + 10, carpet);
        world.setBlock(i + 5, j + 0, k + 11, carpet);
        world.setBlock(i + 5, j + 0, k + 12, carpet);
        world.setBlock(i + 5, j + 0, k + 13, carpet);
        world.setBlock(i + 5, j + 0, k + 14, carpet);
        world.setBlock(i + 5, j + 0, k + 15, carpet);
        world.setBlock(i + 5, j + 0, k + 16, carpet);
        world.setBlock(i + 5, j + 0, k + 17, carpet);
        world.setBlock(i + 5, j + 1, k + 0, glass);
        world.setBlock(i + 5, j + 1, k + 17, glass);
        world.setBlock(i + 5, j + 2, k + 0, glass);
        world.setBlock(i + 5, j + 2, k + 17, glass);
        world.setBlock(i + 5, j + 3, k + 0, glass);
        world.setBlock(i + 5, j + 3, k + 17, glass);
        world.setBlock(i + 5, j + 4, k + 0, glass);
        world.setBlock(i + 5, j + 4, k + 17, glass);
        world.setBlock(i + 5, j + 5, k + 0, glass);
        world.setBlock(i + 5, j + 5, k + 8, lamp);
        world.setBlock(i + 5, j + 5, k + 9, lamp);
        world.setBlock(i + 5, j + 5, k + 17, glass);
        world.setBlock(i + 5, j + 6, k + 0, glass);
        world.setBlock(i + 5, j + 6, k + 17, glass);
        world.setBlock(i + 5, j + 7, k + 0, glass);
        world.setBlock(i + 5, j + 7, k + 1, carpet);
        world.setBlock(i + 5, j + 7, k + 2, carpet);
        world.setBlock(i + 5, j + 7, k + 3, carpet);
        world.setBlock(i + 5, j + 7, k + 4, carpet);
        world.setBlock(i + 5, j + 7, k + 5, carpet);
        world.setBlock(i + 5, j + 7, k + 6, carpet);
        world.setBlock(i + 5, j + 7, k + 7, carpet);
        world.setBlock(i + 5, j + 7, k + 8, carpet);
        world.setBlock(i + 5, j + 7, k + 9, carpet);
        world.setBlock(i + 5, j + 7, k + 10, carpet);
        world.setBlock(i + 5, j + 7, k + 11, carpet);
        world.setBlock(i + 5, j + 7, k + 12, carpet);
        world.setBlock(i + 5, j + 7, k + 13, carpet);
        world.setBlock(i + 5, j + 7, k + 14, carpet);
        world.setBlock(i + 5, j + 7, k + 15, carpet);
        world.setBlock(i + 5, j + 7, k + 16, carpet);
        world.setBlock(i + 5, j + 7, k + 17, glass);
        world.setBlock(i + 5, j + 8, k + 0, glass);
        world.setBlock(i + 5, j + 8, k + 1, carpet);
        world.setBlock(i + 5, j + 8, k + 2, carpet);
        world.setBlock(i + 5, j + 8, k + 3, carpet);
        world.setBlock(i + 5, j + 8, k + 4, carpet);
        world.setBlock(i + 5, j + 8, k + 5, carpet);
        world.setBlock(i + 5, j + 8, k + 6, carpet);
        world.setBlock(i + 5, j + 8, k + 7, carpet);
        world.setBlock(i + 5, j + 8, k + 8, carpet);
        world.setBlock(i + 5, j + 8, k + 9, carpet);
        world.setBlock(i + 5, j + 8, k + 10, carpet);
        world.setBlock(i + 5, j + 8, k + 11, carpet);
        world.setBlock(i + 5, j + 8, k + 12, carpet);
        world.setBlock(i + 5, j + 8, k + 13, carpet);
        world.setBlock(i + 5, j + 8, k + 14, carpet);
        world.setBlock(i + 5, j + 8, k + 15, carpet);
        world.setBlock(i + 5, j + 8, k + 16, carpet);
        world.setBlock(i + 5, j + 8, k + 17, glass);
        world.setBlock(i + 5, j + 9, k + 0, glass);
        world.setBlock(i + 5, j + 9, k + 6, stair, 2, 2);
        world.setBlock(i + 5, j + 9, k + 7, stair, 1, 2);
        world.setBlock(i + 5, j + 9, k + 8, slab, 3, 2);
        world.setBlock(i + 5, j + 9, k + 9, slab, 3, 2);
        world.setBlock(i + 5, j + 9, k + 10, stair, 1, 2);
        world.setBlock(i + 5, j + 9, k + 11, stair, 3, 2);
        world.setBlock(i + 5, j + 9, k + 17, glass);
        world.setBlock(i + 5, j + 10, k + 0, glass);
        world.setBlock(i + 5, j + 10, k + 17, glass);
        world.setBlock(i + 5, j + 11, k + 0, glass);
        world.setBlock(i + 5, j + 11, k + 17, glass);
        world.setBlock(i + 5, j + 12, k + 0, glass);
        world.setBlock(i + 5, j + 12, k + 17, glass);
        world.setBlock(i + 5, j + 13, k + 0, glass);
        world.setBlock(i + 5, j + 13, k + 17, glass);
        world.setBlock(i + 5, j + 14, k + 0, glass);
        world.setBlock(i + 5, j + 14, k + 1, carpet);
        world.setBlock(i + 5, j + 14, k + 2, carpet);
        world.setBlock(i + 5, j + 14, k + 3, carpet);
        world.setBlock(i + 5, j + 14, k + 4, carpet);
        world.setBlock(i + 5, j + 14, k + 5, carpet);
        world.setBlock(i + 5, j + 14, k + 6, carpet);
        world.setBlock(i + 5, j + 14, k + 7, carpet);
        world.setBlock(i + 5, j + 14, k + 8, carpet);
        world.setBlock(i + 5, j + 14, k + 9, carpet);
        world.setBlock(i + 5, j + 14, k + 10, carpet);
        world.setBlock(i + 5, j + 14, k + 11, carpet);
        world.setBlock(i + 5, j + 14, k + 12, carpet);
        world.setBlock(i + 5, j + 14, k + 13, carpet);
        world.setBlock(i + 5, j + 14, k + 14, carpet);
        world.setBlock(i + 5, j + 14, k + 15, carpet);
        world.setBlock(i + 5, j + 14, k + 16, carpet);
        world.setBlock(i + 5, j + 14, k + 17, glass);
        world.setBlock(i + 5, j + 15, k + 0, glass);
        world.setBlock(i + 5, j + 15, k + 1, carpet);
        world.setBlock(i + 5, j + 15, k + 2, carpet);
        world.setBlock(i + 5, j + 15, k + 3, carpet);
        world.setBlock(i + 5, j + 15, k + 4, carpet);
        world.setBlock(i + 5, j + 15, k + 5, carpet);
        world.setBlock(i + 5, j + 15, k + 6, carpet);
        world.setBlock(i + 5, j + 15, k + 7, carpet);
        world.setBlock(i + 5, j + 15, k + 8, carpet);
        world.setBlock(i + 5, j + 15, k + 9, carpet);
        world.setBlock(i + 5, j + 15, k + 10, carpet);
        world.setBlock(i + 5, j + 15, k + 11, carpet);
        world.setBlock(i + 5, j + 15, k + 12, carpet);
        world.setBlock(i + 5, j + 15, k + 13, carpet);
        world.setBlock(i + 5, j + 15, k + 14, carpet);
        world.setBlock(i + 5, j + 15, k + 15, carpet);
        world.setBlock(i + 5, j + 15, k + 16, carpet);
        world.setBlock(i + 5, j + 15, k + 17, glass);
        world.setBlock(i + 5, j + 16, k + 0, glass);
        world.setBlock(i + 5, j + 16, k + 17, glass);
        world.setBlock(i + 5, j + 17, k + 0, glass);
        world.setBlock(i + 5, j + 17, k + 17, glass);
        world.setBlock(i + 5, j + 18, k + 0, glass);
        world.setBlock(i + 5, j + 18, k + 17, glass);
        world.setBlock(i + 5, j + 19, k + 0, glass);
        world.setBlock(i + 5, j + 19, k + 17, glass);
        world.setBlock(i + 5, j + 20, k + 0, glass);
        world.setBlock(i + 5, j + 20, k + 17, glass);
        world.setBlock(i + 5, j + 21, k + 0, glass);
        world.setBlock(i + 5, j + 21, k + 1, stone);
        world.setBlock(i + 5, j + 21, k + 2, stone);
        world.setBlock(i + 5, j + 21, k + 3, stone);
        world.setBlock(i + 5, j + 21, k + 4, stone);
        world.setBlock(i + 5, j + 21, k + 5, stone);
        world.setBlock(i + 5, j + 21, k + 6, lamp);
        world.setBlock(i + 5, j + 21, k + 7, stone);
        world.setBlock(i + 5, j + 21, k + 8, stone);
        world.setBlock(i + 5, j + 21, k + 9, stone);
        world.setBlock(i + 5, j + 21, k + 10, stone);
        world.setBlock(i + 5, j + 21, k + 11, stone);
        world.setBlock(i + 5, j + 21, k + 12, stone);
        world.setBlock(i + 5, j + 21, k + 13, stone);
        world.setBlock(i + 5, j + 21, k + 14, stone);
        world.setBlock(i + 5, j + 21, k + 15, stone);
        world.setBlock(i + 5, j + 21, k + 16, stone);
        world.setBlock(i + 5, j + 21, k + 17, glass);
        world.setBlock(i + 6, j + 0, k + 0, carpet);
        world.setBlock(i + 6, j + 0, k + 1, carpet);
        world.setBlock(i + 6, j + 0, k + 2, carpet);
        world.setBlock(i + 6, j + 0, k + 3, carpet);
        world.setBlock(i + 6, j + 0, k + 4, carpet);
        world.setBlock(i + 6, j + 0, k + 5, carpet);
        world.setBlock(i + 6, j + 0, k + 6, carpet);
        world.setBlock(i + 6, j + 0, k + 7, carpet);
        world.setBlock(i + 6, j + 0, k + 8, carpet);
        world.setBlock(i + 6, j + 0, k + 9, carpet);
        world.setBlock(i + 6, j + 0, k + 10, carpet);
        world.setBlock(i + 6, j + 0, k + 11, carpet);
        world.setBlock(i + 6, j + 0, k + 12, carpet);
        world.setBlock(i + 6, j + 0, k + 13, carpet);
        world.setBlock(i + 6, j + 0, k + 14, carpet);
        world.setBlock(i + 6, j + 0, k + 15, carpet);
        world.setBlock(i + 6, j + 0, k + 16, carpet);
        world.setBlock(i + 6, j + 0, k + 17, carpet);
        world.setBlock(i + 6, j + 1, k + 0, glass);
        world.setBlock(i + 6, j + 1, k + 17, glass);
        world.setBlock(i + 6, j + 2, k + 0, glass);
        world.setBlock(i + 6, j + 2, k + 17, glass);
        world.setBlock(i + 6, j + 3, k + 0, glass);
        world.setBlock(i + 6, j + 3, k + 17, glass);
        world.setBlock(i + 6, j + 4, k + 0, glass);
        world.setBlock(i + 6, j + 4, k + 17, glass);
        world.setBlock(i + 6, j + 5, k + 0, glass);
        world.setBlock(i + 6, j + 5, k + 17, glass);
        world.setBlock(i + 6, j + 6, k + 0, glass);
        world.setBlock(i + 6, j + 6, k + 17, glass);
        world.setBlock(i + 6, j + 7, k + 0, glass);
        world.setBlock(i + 6, j + 7, k + 1, carpet);
        world.setBlock(i + 6, j + 7, k + 2, carpet);
        world.setBlock(i + 6, j + 7, k + 3, carpet);
        world.setBlock(i + 6, j + 7, k + 4, carpet);
        world.setBlock(i + 6, j + 7, k + 5, carpet);
        world.setBlock(i + 6, j + 7, k + 6, carpet);
        world.setBlock(i + 6, j + 7, k + 7, carpet);
        world.setBlock(i + 6, j + 7, k + 8, carpet);
        world.setBlock(i + 6, j + 7, k + 9, carpet);
        world.setBlock(i + 6, j + 7, k + 10, carpet);
        world.setBlock(i + 6, j + 7, k + 11, carpet);
        world.setBlock(i + 6, j + 7, k + 12, carpet);
        world.setBlock(i + 6, j + 7, k + 13, carpet);
        world.setBlock(i + 6, j + 7, k + 14, carpet);
        world.setBlock(i + 6, j + 7, k + 15, carpet);
        world.setBlock(i + 6, j + 7, k + 16, carpet);
        world.setBlock(i + 6, j + 7, k + 17, glass);
        world.setBlock(i + 6, j + 8, k + 0, glass);
        world.setBlock(i + 6, j + 8, k + 1, carpet);
        world.setBlock(i + 6, j + 8, k + 2, carpet);
        world.setBlock(i + 6, j + 8, k + 3, carpet);
        world.setBlock(i + 6, j + 8, k + 4, carpet);
        world.setBlock(i + 6, j + 8, k + 5, carpet);
        world.setBlock(i + 6, j + 8, k + 6, carpet);
        world.setBlock(i + 6, j + 8, k + 7, carpet);
        world.setBlock(i + 6, j + 8, k + 8, carpet);
        world.setBlock(i + 6, j + 8, k + 9, carpet);
        world.setBlock(i + 6, j + 8, k + 10, carpet);
        world.setBlock(i + 6, j + 8, k + 11, carpet);
        world.setBlock(i + 6, j + 8, k + 12, carpet);
        world.setBlock(i + 6, j + 8, k + 13, carpet);
        world.setBlock(i + 6, j + 8, k + 14, carpet);
        world.setBlock(i + 6, j + 8, k + 15, carpet);
        world.setBlock(i + 6, j + 8, k + 16, carpet);
        world.setBlock(i + 6, j + 8, k + 17, glass);
        world.setBlock(i + 6, j + 9, k + 0, glass);
        world.setBlock(i + 6, j + 9, k + 17, glass);
        world.setBlock(i + 6, j + 10, k + 0, glass);
        world.setBlock(i + 6, j + 10, k + 17, glass);
        world.setBlock(i + 6, j + 11, k + 0, glass);
        world.setBlock(i + 6, j + 11, k + 17, glass);
        world.setBlock(i + 6, j + 12, k + 0, glass);
        world.setBlock(i + 6, j + 12, k + 17, glass);
        world.setBlock(i + 6, j + 13, k + 0, glass);
        world.setBlock(i + 6, j + 13, k + 17, glass);
        world.setBlock(i + 6, j + 14, k + 0, glass);
        world.setBlock(i + 6, j + 14, k + 1, carpet);
        world.setBlock(i + 6, j + 14, k + 2, carpet);
        world.setBlock(i + 6, j + 14, k + 3, carpet);
        world.setBlock(i + 6, j + 14, k + 4, carpet);
        world.setBlock(i + 6, j + 14, k + 5, carpet);
        world.setBlock(i + 6, j + 14, k + 6, carpet);
        world.setBlock(i + 6, j + 14, k + 7, carpet);
        world.setBlock(i + 6, j + 14, k + 8, carpet);
        world.setBlock(i + 6, j + 14, k + 9, carpet);
        world.setBlock(i + 6, j + 14, k + 10, carpet);
        world.setBlock(i + 6, j + 14, k + 11, carpet);
        world.setBlock(i + 6, j + 14, k + 12, carpet);
        world.setBlock(i + 6, j + 14, k + 13, carpet);
        world.setBlock(i + 6, j + 14, k + 14, carpet);
        world.setBlock(i + 6, j + 14, k + 15, carpet);
        world.setBlock(i + 6, j + 14, k + 16, carpet);
        world.setBlock(i + 6, j + 14, k + 17, glass);
        world.setBlock(i + 6, j + 15, k + 0, glass);
        world.setBlock(i + 6, j + 15, k + 1, carpet);
        world.setBlock(i + 6, j + 15, k + 2, carpet);
        world.setBlock(i + 6, j + 15, k + 3, carpet);
        world.setBlock(i + 6, j + 15, k + 4, carpet);
        world.setBlock(i + 6, j + 15, k + 5, carpet);
        world.setBlock(i + 6, j + 15, k + 6, carpet);
        world.setBlock(i + 6, j + 15, k + 7, carpet);
        world.setBlock(i + 6, j + 15, k + 8, carpet);
        world.setBlock(i + 6, j + 15, k + 9, carpet);
        world.setBlock(i + 6, j + 15, k + 10, carpet);
        world.setBlock(i + 6, j + 15, k + 11, carpet);
        world.setBlock(i + 6, j + 15, k + 12, carpet);
        world.setBlock(i + 6, j + 15, k + 13, carpet);
        world.setBlock(i + 6, j + 15, k + 14, carpet);
        world.setBlock(i + 6, j + 15, k + 15, carpet);
        world.setBlock(i + 6, j + 15, k + 16, carpet);
        world.setBlock(i + 6, j + 15, k + 17, glass);
        world.setBlock(i + 6, j + 16, k + 0, glass);
        world.setBlock(i + 6, j + 16, k + 17, glass);
        world.setBlock(i + 6, j + 17, k + 0, glass);
        world.setBlock(i + 6, j + 17, k + 17, glass);
        world.setBlock(i + 6, j + 18, k + 0, glass);
        world.setBlock(i + 6, j + 18, k + 17, glass);
        world.setBlock(i + 6, j + 19, k + 0, glass);
        world.setBlock(i + 6, j + 19, k + 17, glass);
        world.setBlock(i + 6, j + 20, k + 0, glass);
        world.setBlock(i + 6, j + 20, k + 17, glass);
        world.setBlock(i + 6, j + 21, k + 0, glass);
        world.setBlock(i + 6, j + 21, k + 1, stone);
        world.setBlock(i + 6, j + 21, k + 2, stone);
        world.setBlock(i + 6, j + 21, k + 3, stone);
        world.setBlock(i + 6, j + 21, k + 4, stone);
        world.setBlock(i + 6, j + 21, k + 5, stone);
        world.setBlock(i + 6, j + 21, k + 6, stone);
        world.setBlock(i + 6, j + 21, k + 7, lamp);
        world.setBlock(i + 6, j + 21, k + 8, lamp);
        world.setBlock(i + 6, j + 21, k + 9, lamp);
        world.setBlock(i + 6, j + 21, k + 10, stone);
        world.setBlock(i + 6, j + 21, k + 11, stone);
        world.setBlock(i + 6, j + 21, k + 12, stone);
        world.setBlock(i + 6, j + 21, k + 13, stone);
        world.setBlock(i + 6, j + 21, k + 14, stone);
        world.setBlock(i + 6, j + 21, k + 15, stone);
        world.setBlock(i + 6, j + 21, k + 16, stone);
        world.setBlock(i + 6, j + 21, k + 17, glass);
        world.setBlock(i + 7, j + 0, k + 0, carpet);
        world.setBlock(i + 7, j + 0, k + 1, carpet);
        world.setBlock(i + 7, j + 0, k + 2, carpet);
        world.setBlock(i + 7, j + 0, k + 3, carpet);
        world.setBlock(i + 7, j + 0, k + 4, carpet);
        world.setBlock(i + 7, j + 0, k + 5, carpet);
        world.setBlock(i + 7, j + 0, k + 6, carpet);
        world.setBlock(i + 7, j + 0, k + 7, carpet);
        world.setBlock(i + 7, j + 0, k + 8, carpet);
        world.setBlock(i + 7, j + 0, k + 9, carpet);
        world.setBlock(i + 7, j + 0, k + 10, carpet);
        world.setBlock(i + 7, j + 0, k + 11, carpet);
        world.setBlock(i + 7, j + 0, k + 12, carpet);
        world.setBlock(i + 7, j + 0, k + 13, carpet);
        world.setBlock(i + 7, j + 0, k + 14, carpet);
        world.setBlock(i + 7, j + 0, k + 15, carpet);
        world.setBlock(i + 7, j + 0, k + 16, carpet);
        world.setBlock(i + 7, j + 0, k + 17, carpet);
        world.setBlock(i + 7, j + 1, k + 0, glass);
        world.setBlock(i + 7, j + 1, k + 6, stair);
        world.setBlock(i + 7, j + 1, k + 7, stair);
        world.setBlock(i + 7, j + 1, k + 8, slab, 3, 2);
        world.setBlock(i + 7, j + 1, k + 9, slab, 3, 2);
        world.setBlock(i + 7, j + 1, k + 10, stair);
        world.setBlock(i + 7, j + 1, k + 11, stair);
        world.setBlock(i + 7, j + 1, k + 17, glass);
        world.setBlock(i + 7, j + 2, k + 0, glass);
        world.setBlock(i + 7, j + 2, k + 17, glass);
        world.setBlock(i + 7, j + 3, k + 0, glass);
        world.setBlock(i + 7, j + 3, k + 17, glass);
        world.setBlock(i + 7, j + 4, k + 0, glass);
        world.setBlock(i + 7, j + 4, k + 17, glass);
        world.setBlock(i + 7, j + 5, k + 0, glass);
        world.setBlock(i + 7, j + 5, k + 2, lamp);
        world.setBlock(i + 7, j + 5, k + 15, lamp);
        world.setBlock(i + 7, j + 5, k + 17, glass);
        world.setBlock(i + 7, j + 6, k + 0, glass);
        world.setBlock(i + 7, j + 6, k + 2, fence);
        world.setBlock(i + 7, j + 6, k + 15, fence);
        world.setBlock(i + 7, j + 6, k + 17, glass);
        world.setBlock(i + 7, j + 7, k + 0, glass);
        world.setBlock(i + 7, j + 7, k + 1, carpet);
        world.setBlock(i + 7, j + 7, k + 2, carpet);
        world.setBlock(i + 7, j + 7, k + 3, carpet);
        world.setBlock(i + 7, j + 7, k + 4, carpet);
        world.setBlock(i + 7, j + 7, k + 5, carpet);
        world.setBlock(i + 7, j + 7, k + 6, carpet);
        world.setBlock(i + 7, j + 7, k + 7, carpet);
        world.setBlock(i + 7, j + 7, k + 8, carpet);
        world.setBlock(i + 7, j + 7, k + 9, carpet);
        world.setBlock(i + 7, j + 7, k + 10, carpet);
        world.setBlock(i + 7, j + 7, k + 11, carpet);
        world.setBlock(i + 7, j + 7, k + 12, carpet);
        world.setBlock(i + 7, j + 7, k + 13, carpet);
        world.setBlock(i + 7, j + 7, k + 14, carpet);
        world.setBlock(i + 7, j + 7, k + 15, carpet);
        world.setBlock(i + 7, j + 7, k + 16, carpet);
        world.setBlock(i + 7, j + 7, k + 17, glass);
        world.setBlock(i + 7, j + 8, k + 0, glass);
        world.setBlock(i + 7, j + 8, k + 1, carpet);
        world.setBlock(i + 7, j + 8, k + 2, carpet);
        world.setBlock(i + 7, j + 8, k + 3, carpet);
        world.setBlock(i + 7, j + 8, k + 4, carpet);
        world.setBlock(i + 7, j + 8, k + 5, carpet);
        world.setBlock(i + 7, j + 8, k + 6, carpet);
        world.setBlock(i + 7, j + 8, k + 7, carpet);
        world.setBlock(i + 7, j + 8, k + 8, stair, 1, 2);
        world.setBlock(i + 7, j + 8, k + 9, stair, 1, 2);
        world.setBlock(i + 7, j + 8, k + 10, carpet);
        world.setBlock(i + 7, j + 8, k + 11, carpet);
        world.setBlock(i + 7, j + 8, k + 12, carpet);
        world.setBlock(i + 7, j + 8, k + 13, carpet);
        world.setBlock(i + 7, j + 8, k + 14, carpet);
        world.setBlock(i + 7, j + 8, k + 15, carpet);
        world.setBlock(i + 7, j + 8, k + 16, carpet);
        world.setBlock(i + 7, j + 8, k + 17, glass);
        world.setBlock(i + 7, j + 9, k + 0, glass);
        world.setBlock(i + 7, j + 9, k + 17, glass);
        world.setBlock(i + 7, j + 10, k + 0, glass);
        world.setBlock(i + 7, j + 10, k + 17, glass);
        this.generate2(world, rand, i, j, k, glass, carpet, pane, stone, stair, lamp, slab, fence, door);
        return true;
    }
    
    public boolean generate2(final World world, final Random rand, final int i, final int j, final int k, final Block glass, final Block carpet, final Block pane, final Block stone, final Block stair, final Block lamp, final Block slab, final Block fence, final Block door) {
        world.setBlock(i + 7, j + 11, k + 0, glass);
        world.setBlock(i + 7, j + 11, k + 17, glass);
        world.setBlock(i + 7, j + 12, k + 0, glass);
        world.setBlock(i + 7, j + 12, k + 17, glass);
        world.setBlock(i + 7, j + 13, k + 0, glass);
        world.setBlock(i + 7, j + 13, k + 17, glass);
        world.setBlock(i + 7, j + 14, k + 0, glass);
        world.setBlock(i + 7, j + 14, k + 1, carpet);
        world.setBlock(i + 7, j + 14, k + 2, carpet);
        world.setBlock(i + 7, j + 14, k + 3, carpet);
        world.setBlock(i + 7, j + 14, k + 4, carpet);
        world.setBlock(i + 7, j + 14, k + 5, carpet);
        world.setBlock(i + 7, j + 14, k + 6, carpet);
        world.setBlock(i + 7, j + 14, k + 7, carpet);
        world.setBlock(i + 7, j + 14, k + 8, carpet);
        world.setBlock(i + 7, j + 14, k + 9, carpet);
        world.setBlock(i + 7, j + 14, k + 10, carpet);
        world.setBlock(i + 7, j + 14, k + 11, carpet);
        world.setBlock(i + 7, j + 14, k + 12, carpet);
        world.setBlock(i + 7, j + 14, k + 13, carpet);
        world.setBlock(i + 7, j + 14, k + 14, carpet);
        world.setBlock(i + 7, j + 14, k + 15, carpet);
        world.setBlock(i + 7, j + 14, k + 16, carpet);
        world.setBlock(i + 7, j + 14, k + 17, glass);
        world.setBlock(i + 7, j + 15, k + 0, glass);
        world.setBlock(i + 7, j + 15, k + 1, carpet);
        world.setBlock(i + 7, j + 15, k + 2, carpet);
        world.setBlock(i + 7, j + 15, k + 3, carpet);
        world.setBlock(i + 7, j + 15, k + 4, carpet);
        world.setBlock(i + 7, j + 15, k + 5, carpet);
        world.setBlock(i + 7, j + 15, k + 6, carpet);
        world.setBlock(i + 7, j + 15, k + 7, carpet);
        world.setBlock(i + 7, j + 15, k + 8, carpet);
        world.setBlock(i + 7, j + 15, k + 9, carpet);
        world.setBlock(i + 7, j + 15, k + 10, carpet);
        world.setBlock(i + 7, j + 15, k + 11, carpet);
        world.setBlock(i + 7, j + 15, k + 12, carpet);
        world.setBlock(i + 7, j + 15, k + 13, carpet);
        world.setBlock(i + 7, j + 15, k + 14, carpet);
        world.setBlock(i + 7, j + 15, k + 15, carpet);
        world.setBlock(i + 7, j + 15, k + 16, carpet);
        world.setBlock(i + 7, j + 15, k + 17, glass);
        world.setBlock(i + 7, j + 16, k + 0, glass);
        world.setBlock(i + 7, j + 16, k + 6, stone);
        world.setBlock(i + 7, j + 16, k + 7, stair, 5, 2);
        world.setBlock(i + 7, j + 16, k + 8, stone);
        world.setBlock(i + 7, j + 16, k + 9, stone);
        world.setBlock(i + 7, j + 16, k + 10, stair, 5, 2);
        world.setBlock(i + 7, j + 16, k + 11, stone);
        world.setBlock(i + 7, j + 16, k + 17, glass);
        world.setBlock(i + 7, j + 17, k + 0, glass);
        world.setBlock(i + 7, j + 17, k + 6, pane);
        world.setBlock(i + 7, j + 17, k + 7, pane);
        world.setBlock(i + 7, j + 17, k + 8, pane);
        world.setBlock(i + 7, j + 17, k + 9, pane);
        world.setBlock(i + 7, j + 17, k + 10, pane);
        world.setBlock(i + 7, j + 17, k + 11, pane);
        world.setBlock(i + 7, j + 17, k + 17, glass);
        world.setBlock(i + 7, j + 18, k + 0, glass);
        world.setBlock(i + 7, j + 18, k + 6, pane);
        world.setBlock(i + 7, j + 18, k + 7, pane);
        world.setBlock(i + 7, j + 18, k + 8, pane);
        world.setBlock(i + 7, j + 18, k + 9, pane);
        world.setBlock(i + 7, j + 18, k + 10, pane);
        world.setBlock(i + 7, j + 18, k + 11, pane);
        world.setBlock(i + 7, j + 18, k + 17, glass);
        world.setBlock(i + 7, j + 19, k + 0, glass);
        world.setBlock(i + 7, j + 19, k + 6, pane);
        world.setBlock(i + 7, j + 19, k + 7, pane);
        world.setBlock(i + 7, j + 19, k + 8, pane);
        world.setBlock(i + 7, j + 19, k + 9, pane);
        world.setBlock(i + 7, j + 19, k + 10, pane);
        world.setBlock(i + 7, j + 19, k + 11, pane);
        world.setBlock(i + 7, j + 19, k + 17, glass);
        world.setBlock(i + 7, j + 20, k + 0, glass);
        world.setBlock(i + 7, j + 20, k + 6, stone);
        world.setBlock(i + 7, j + 20, k + 7, stone);
        world.setBlock(i + 7, j + 20, k + 8, stone);
        world.setBlock(i + 7, j + 20, k + 9, stone);
        world.setBlock(i + 7, j + 20, k + 10, stone);
        world.setBlock(i + 7, j + 20, k + 11, stone);
        world.setBlock(i + 7, j + 20, k + 17, glass);
        world.setBlock(i + 7, j + 21, k + 0, glass);
        world.setBlock(i + 7, j + 21, k + 1, stone);
        world.setBlock(i + 7, j + 21, k + 2, stone);
        world.setBlock(i + 7, j + 21, k + 3, stone);
        world.setBlock(i + 7, j + 21, k + 4, stone);
        world.setBlock(i + 7, j + 21, k + 5, stone);
        world.setBlock(i + 7, j + 21, k + 6, stone);
        world.setBlock(i + 7, j + 21, k + 7, stone);
        world.setBlock(i + 7, j + 21, k + 8, stone);
        world.setBlock(i + 7, j + 21, k + 9, stone);
        world.setBlock(i + 7, j + 21, k + 10, lamp);
        world.setBlock(i + 7, j + 21, k + 11, stone);
        world.setBlock(i + 7, j + 21, k + 12, stone);
        world.setBlock(i + 7, j + 21, k + 13, stone);
        world.setBlock(i + 7, j + 21, k + 14, stone);
        world.setBlock(i + 7, j + 21, k + 15, stone);
        world.setBlock(i + 7, j + 21, k + 16, stone);
        world.setBlock(i + 7, j + 21, k + 17, glass);
        world.setBlock(i + 8, j + 0, k + 0, carpet);
        world.setBlock(i + 8, j + 0, k + 1, carpet);
        world.setBlock(i + 8, j + 0, k + 2, carpet);
        world.setBlock(i + 8, j + 0, k + 3, carpet);
        world.setBlock(i + 8, j + 0, k + 4, carpet);
        world.setBlock(i + 8, j + 0, k + 5, carpet);
        world.setBlock(i + 8, j + 0, k + 6, carpet);
        world.setBlock(i + 8, j + 0, k + 7, carpet);
        world.setBlock(i + 8, j + 0, k + 8, carpet);
        world.setBlock(i + 8, j + 0, k + 9, carpet);
        world.setBlock(i + 8, j + 0, k + 10, carpet);
        world.setBlock(i + 8, j + 0, k + 11, carpet);
        world.setBlock(i + 8, j + 0, k + 12, carpet);
        world.setBlock(i + 8, j + 0, k + 13, carpet);
        world.setBlock(i + 8, j + 0, k + 14, carpet);
        world.setBlock(i + 8, j + 0, k + 15, carpet);
        world.setBlock(i + 8, j + 0, k + 16, carpet);
        world.setBlock(i + 8, j + 0, k + 17, carpet);
        world.setBlock(i + 8, j + 1, k + 0, glass);
        world.setBlock(i + 8, j + 1, k + 6, stair, 2, 2);
        world.setBlock(i + 8, j + 1, k + 7, stone);
        world.setBlock(i + 8, j + 1, k + 8, slab, 3, 2);
        world.setBlock(i + 8, j + 1, k + 9, slab, 3, 2);
        world.setBlock(i + 8, j + 1, k + 10, stone);
        world.setBlock(i + 8, j + 1, k + 11, stair, 3, 2);
        world.setBlock(i + 8, j + 1, k + 17, glass);
        world.setBlock(i + 8, j + 2, k + 0, glass);
        world.setBlock(i + 8, j + 2, k + 7, stone);
        world.setBlock(i + 8, j + 2, k + 10, stone);
        world.setBlock(i + 8, j + 2, k + 17, glass);
        world.setBlock(i + 8, j + 3, k + 0, glass);
        world.setBlock(i + 8, j + 3, k + 7, stone);
        world.setBlock(i + 8, j + 3, k + 8, stair, 4, 2);
        world.setBlock(i + 8, j + 3, k + 9, stair, 4, 2);
        world.setBlock(i + 8, j + 3, k + 10, stone);
        world.setBlock(i + 8, j + 3, k + 17, glass);
        world.setBlock(i + 8, j + 4, k + 0, glass);
        world.setBlock(i + 8, j + 4, k + 7, stone);
        world.setBlock(i + 8, j + 4, k + 8, stone);
        world.setBlock(i + 8, j + 4, k + 9, stone);
        world.setBlock(i + 8, j + 4, k + 10, stone);
        world.setBlock(i + 8, j + 4, k + 17, glass);
        world.setBlock(i + 8, j + 5, k + 0, glass);
        world.setBlock(i + 8, j + 5, k + 7, stone);
        world.setBlock(i + 8, j + 5, k + 8, stone);
        world.setBlock(i + 8, j + 5, k + 9, stone);
        world.setBlock(i + 8, j + 5, k + 10, stone);
        world.setBlock(i + 8, j + 5, k + 17, glass);
        world.setBlock(i + 8, j + 6, k + 0, glass);
        world.setBlock(i + 8, j + 6, k + 7, stone);
        world.setBlock(i + 8, j + 6, k + 8, stone);
        world.setBlock(i + 8, j + 6, k + 9, stone);
        world.setBlock(i + 8, j + 6, k + 10, stone);
        world.setBlock(i + 8, j + 6, k + 17, glass);
        world.setBlock(i + 8, j + 7, k + 0, glass);
        world.setBlock(i + 8, j + 7, k + 1, carpet);
        world.setBlock(i + 8, j + 7, k + 2, carpet);
        world.setBlock(i + 8, j + 7, k + 3, carpet);
        world.setBlock(i + 8, j + 7, k + 4, carpet);
        world.setBlock(i + 8, j + 7, k + 5, carpet);
        world.setBlock(i + 8, j + 7, k + 6, carpet);
        world.setBlock(i + 8, j + 7, k + 7, carpet);
        world.setBlock(i + 8, j + 7, k + 8, stair, 1, 2);
        world.setBlock(i + 8, j + 7, k + 9, stair, 1, 2);
        world.setBlock(i + 8, j + 7, k + 10, carpet);
        world.setBlock(i + 8, j + 7, k + 11, carpet);
        world.setBlock(i + 8, j + 7, k + 12, carpet);
        world.setBlock(i + 8, j + 7, k + 13, carpet);
        world.setBlock(i + 8, j + 7, k + 14, carpet);
        world.setBlock(i + 8, j + 7, k + 15, carpet);
        world.setBlock(i + 8, j + 7, k + 16, carpet);
        world.setBlock(i + 8, j + 7, k + 17, glass);
        world.setBlock(i + 8, j + 8, k + 0, glass);
        world.setBlock(i + 8, j + 8, k + 1, carpet);
        world.setBlock(i + 8, j + 8, k + 2, carpet);
        world.setBlock(i + 8, j + 8, k + 3, carpet);
        world.setBlock(i + 8, j + 8, k + 4, carpet);
        world.setBlock(i + 8, j + 8, k + 5, carpet);
        world.setBlock(i + 8, j + 8, k + 6, carpet);
        world.setBlock(i + 8, j + 8, k + 7, carpet);
        world.setBlock(i + 8, j + 8, k + 10, carpet);
        world.setBlock(i + 8, j + 8, k + 11, carpet);
        world.setBlock(i + 8, j + 8, k + 12, carpet);
        world.setBlock(i + 8, j + 8, k + 13, carpet);
        world.setBlock(i + 8, j + 8, k + 14, carpet);
        world.setBlock(i + 8, j + 8, k + 15, carpet);
        world.setBlock(i + 8, j + 8, k + 16, carpet);
        world.setBlock(i + 8, j + 8, k + 17, glass);
        world.setBlock(i + 8, j + 9, k + 0, glass);
        world.setBlock(i + 8, j + 9, k + 2, slab, 11, 2);
        world.setBlock(i + 8, j + 9, k + 3, slab, 11, 2);
        world.setBlock(i + 8, j + 9, k + 4, stone);
        world.setBlock(i + 8, j + 9, k + 13, stone);
        world.setBlock(i + 8, j + 9, k + 14, slab, 11, 2);
        world.setBlock(i + 8, j + 9, k + 15, slab, 11, 2);
        world.setBlock(i + 8, j + 9, k + 17, glass);
        world.setBlock(i + 8, j + 10, k + 0, glass);
        world.setBlock(i + 8, j + 10, k + 4, fence);
        world.setBlock(i + 8, j + 10, k + 13, fence);
        world.setBlock(i + 8, j + 10, k + 17, glass);
        world.setBlock(i + 8, j + 11, k + 0, glass);
        world.setBlock(i + 8, j + 11, k + 4, fence);
        world.setBlock(i + 8, j + 11, k + 13, fence);
        world.setBlock(i + 8, j + 11, k + 17, glass);
        world.setBlock(i + 8, j + 12, k + 0, glass);
        world.setBlock(i + 8, j + 12, k + 4, fence);
        world.setBlock(i + 8, j + 12, k + 13, fence);
        world.setBlock(i + 8, j + 12, k + 17, glass);
        world.setBlock(i + 8, j + 13, k + 0, glass);
        world.setBlock(i + 8, j + 13, k + 4, fence);
        world.setBlock(i + 8, j + 13, k + 13, fence);
        world.setBlock(i + 8, j + 13, k + 17, glass);
        world.setBlock(i + 8, j + 14, k + 0, glass);
        world.setBlock(i + 8, j + 14, k + 1, carpet);
        world.setBlock(i + 8, j + 14, k + 2, carpet);
        world.setBlock(i + 8, j + 14, k + 3, carpet);
        world.setBlock(i + 8, j + 14, k + 4, carpet);
        world.setBlock(i + 8, j + 14, k + 5, carpet);
        world.setBlock(i + 8, j + 14, k + 6, carpet);
        world.setBlock(i + 8, j + 14, k + 7, carpet);
        world.setBlock(i + 8, j + 14, k + 8, carpet);
        world.setBlock(i + 8, j + 14, k + 9, carpet);
        world.setBlock(i + 8, j + 14, k + 10, carpet);
        world.setBlock(i + 8, j + 14, k + 11, carpet);
        world.setBlock(i + 8, j + 14, k + 12, carpet);
        world.setBlock(i + 8, j + 14, k + 13, carpet);
        world.setBlock(i + 8, j + 14, k + 14, carpet);
        world.setBlock(i + 8, j + 14, k + 15, carpet);
        world.setBlock(i + 8, j + 14, k + 16, carpet);
        world.setBlock(i + 8, j + 14, k + 17, glass);
        world.setBlock(i + 8, j + 15, k + 0, glass);
        world.setBlock(i + 8, j + 15, k + 1, carpet);
        world.setBlock(i + 8, j + 15, k + 2, carpet);
        world.setBlock(i + 8, j + 15, k + 3, carpet);
        world.setBlock(i + 8, j + 15, k + 4, carpet);
        world.setBlock(i + 8, j + 15, k + 5, carpet);
        world.setBlock(i + 8, j + 15, k + 6, carpet);
        world.setBlock(i + 8, j + 15, k + 7, carpet);
        world.setBlock(i + 8, j + 15, k + 8, carpet);
        world.setBlock(i + 8, j + 15, k + 9, carpet);
        world.setBlock(i + 8, j + 15, k + 10, carpet);
        world.setBlock(i + 8, j + 15, k + 11, carpet);
        world.setBlock(i + 8, j + 15, k + 12, carpet);
        world.setBlock(i + 8, j + 15, k + 13, carpet);
        world.setBlock(i + 8, j + 15, k + 14, carpet);
        world.setBlock(i + 8, j + 15, k + 15, carpet);
        world.setBlock(i + 8, j + 15, k + 16, carpet);
        world.setBlock(i + 8, j + 15, k + 17, glass);
        world.setBlock(i + 8, j + 16, k + 0, glass);
        world.setBlock(i + 8, j + 16, k + 6, stair, 7, 2);
        world.setBlock(i + 8, j + 16, k + 8, stair, 5, 2);
        world.setBlock(i + 8, j + 16, k + 9, stair, 5, 2);
        world.setBlock(i + 8, j + 16, k + 11, stair, 6, 2);
        world.setBlock(i + 8, j + 16, k + 17, glass);
        world.setBlock(i + 8, j + 17, k + 0, glass);
        world.setBlock(i + 8, j + 17, k + 6, pane);
        world.setBlock(i + 8, j + 17, k + 11, pane);
        world.setBlock(i + 8, j + 17, k + 17, glass);
        world.setBlock(i + 8, j + 18, k + 0, glass);
        world.setBlock(i + 8, j + 18, k + 6, pane);
        world.setBlock(i + 8, j + 18, k + 11, pane);
        world.setBlock(i + 8, j + 18, k + 17, glass);
        world.setBlock(i + 8, j + 19, k + 0, glass);
        world.setBlock(i + 8, j + 19, k + 6, pane);
        world.setBlock(i + 8, j + 19, k + 11, pane);
        world.setBlock(i + 8, j + 19, k + 17, glass);
        world.setBlock(i + 8, j + 20, k + 0, glass);
        world.setBlock(i + 8, j + 20, k + 6, stone);
        world.setBlock(i + 8, j + 20, k + 11, stone);
        world.setBlock(i + 8, j + 20, k + 17, glass);
        world.setBlock(i + 8, j + 21, k + 0, glass);
        world.setBlock(i + 8, j + 21, k + 1, stone);
        world.setBlock(i + 8, j + 21, k + 2, stone);
        world.setBlock(i + 8, j + 21, k + 3, stone);
        world.setBlock(i + 8, j + 21, k + 4, stone);
        world.setBlock(i + 8, j + 21, k + 5, stone);
        world.setBlock(i + 8, j + 21, k + 6, stone);
        world.setBlock(i + 8, j + 21, k + 7, stone);
        world.setBlock(i + 8, j + 21, k + 8, stone);
        world.setBlock(i + 8, j + 21, k + 9, stone);
        world.setBlock(i + 8, j + 21, k + 10, lamp);
        world.setBlock(i + 8, j + 21, k + 11, stone);
        world.setBlock(i + 8, j + 21, k + 12, stone);
        world.setBlock(i + 8, j + 21, k + 13, stone);
        world.setBlock(i + 8, j + 21, k + 14, stone);
        world.setBlock(i + 8, j + 21, k + 15, stone);
        world.setBlock(i + 8, j + 21, k + 16, stone);
        world.setBlock(i + 8, j + 21, k + 17, glass);
        world.setBlock(i + 9, j + 0, k + 0, carpet);
        world.setBlock(i + 9, j + 0, k + 1, carpet);
        world.setBlock(i + 9, j + 0, k + 2, carpet);
        world.setBlock(i + 9, j + 0, k + 3, carpet);
        world.setBlock(i + 9, j + 0, k + 4, carpet);
        world.setBlock(i + 9, j + 0, k + 5, carpet);
        world.setBlock(i + 9, j + 0, k + 6, carpet);
        world.setBlock(i + 9, j + 0, k + 7, carpet);
        world.setBlock(i + 9, j + 0, k + 8, Blocks.netherrack);
        world.setBlock(i + 9, j + 0, k + 9, Blocks.netherrack);
        world.setBlock(i + 9, j + 0, k + 10, carpet);
        world.setBlock(i + 9, j + 0, k + 11, carpet);
        world.setBlock(i + 9, j + 0, k + 12, carpet);
        world.setBlock(i + 9, j + 0, k + 13, carpet);
        world.setBlock(i + 9, j + 0, k + 14, carpet);
        world.setBlock(i + 9, j + 0, k + 15, carpet);
        world.setBlock(i + 9, j + 0, k + 16, carpet);
        world.setBlock(i + 9, j + 0, k + 17, carpet);
        world.setBlock(i + 9, j + 1, k + 0, glass);
        world.setBlock(i + 9, j + 1, k + 3, glass);
        world.setBlock(i + 9, j + 1, k + 4, glass);
        world.setBlock(i + 9, j + 1, k + 5, glass);
        world.setBlock(i + 9, j + 1, k + 6, glass);
        world.setBlock(i + 9, j + 1, k + 7, stone);
        world.setBlock(i + 9, j + 1, k + 8, (Block)Blocks.fire);
        world.setBlock(i + 9, j + 1, k + 9, (Block)Blocks.fire);
        world.setBlock(i + 9, j + 1, k + 10, stone);
        world.setBlock(i + 9, j + 1, k + 11, glass);
        world.setBlock(i + 9, j + 1, k + 12, glass);
        world.setBlock(i + 9, j + 1, k + 13, glass);
        world.setBlock(i + 9, j + 1, k + 14, glass);
        world.setBlock(i + 9, j + 1, k + 17, glass);
        world.setBlock(i + 9, j + 2, k + 0, glass);
        world.setBlock(i + 9, j + 2, k + 3, glass);
        world.setBlock(i + 9, j + 2, k + 4, glass);
        world.setBlock(i + 9, j + 2, k + 5, glass);
        world.setBlock(i + 9, j + 2, k + 6, glass);
        world.setBlock(i + 9, j + 2, k + 7, stone);
        world.setBlock(i + 9, j + 2, k + 10, stone);
        world.setBlock(i + 9, j + 2, k + 11, glass);
        world.setBlock(i + 9, j + 2, k + 12, glass);
        world.setBlock(i + 9, j + 2, k + 13, glass);
        world.setBlock(i + 9, j + 2, k + 14, glass);
        world.setBlock(i + 9, j + 2, k + 17, glass);
        world.setBlock(i + 9, j + 3, k + 0, glass);
        world.setBlock(i + 9, j + 3, k + 1, glass);
        world.setBlock(i + 9, j + 3, k + 2, glass);
        world.setBlock(i + 9, j + 3, k + 3, glass);
        world.setBlock(i + 9, j + 3, k + 4, glass);
        world.setBlock(i + 9, j + 3, k + 5, glass);
        world.setBlock(i + 9, j + 3, k + 6, glass);
        world.setBlock(i + 9, j + 3, k + 7, glass);
        world.setBlock(i + 9, j + 3, k + 8, stone);
